Workbook

Sheet financial data
A1: id | B1: Причина дубля | C1: Ноябрь 2022 | D1: Декабрь 2022 | E1: Январь 2023 | F1: Февраль 2023 | G1: Март 2023 | H1: Апрель 2023 | I1: Май 2023 | J1: Июнь 2023 | K1: Июль 2023 | L1: Август 2023 | M1: Сентябрь 2023 | N1: Октябрь 2023 | O1: Ноябрь 2023 | P1: Декабрь 2023 | Q1: Январь 2024 | R1: Февраль 2024 | S1: Account
A2: 42 | C2: 36220 | S2: Васильев Артем Александрович
A3: 657 | B3: первая часть оплаты | C3: стоп | S3: Васильев Артем Александрович
A4: 657 | B4: вторая часть оплаты | C4: стоп | S4: Васильев Артем Александрович
A5: 594 | C5: стоп | S5: Васильев Артем Александрович
A6: 665 | C6: 10000 | S6: Васильев Артем Александрович
A7: 637 | C7: 38045 | S7: Соколова Анастасия Викторовна
A8: 419 | S8: Михайлов Андрей Сергеевич
A9: 578 | C9: 82800 | S9: Попова Екатерина Николаевна
A10: 579 | C10: в ноль | S10: Васильев Артем Александрович
A11: 592 | B11: первая часть оплаты | C11: 92302 | S11: Васильев Артем Александрович
A12: 592 | B12: вторая часть оплаты | C12: 12340 | S12: Васильев Артем Александрович
A13: 666 | C13: 110000 | S13: Васильев Артем Александрович
A14: 620 | C14: в ноль | S14: Васильев Артем Александрович
A15: 704 | B15: первая часть оплаты | C15: 35365 | S15: Михайлов Андрей Сергеевич
A16: 704 | B16: вторая часть оплаты | C16: 945 | S16: Михайлов Андрей Сергеевич
A17: 704 | B17: вторая часть оплаты | C17: 4715 | S17: Михайлов Андрей Сергеевич
A18: 16 | S18: Иванова Мария Сергеевна
A19: 379 | C19: 55195 | D19: 55195 | S19: Иванова Мария Сергеевна
A20: 31 | C20: 55100 | D20: 55100 | F20: 44775 | G20: 44775 | H20: 44775 | I20: 44775 | J20: 44775 | K20: 44775 | L20: 44775 | M20: 44775 | N20: 44775 | O20: 44775 | P20: 44775 | Q20: 44775 | R20: 46200 | S20: Васильев Артем Александрович
A21: 572 | B21: изменение ЮЛ | C21: 56200 | D21: стоп | S21: Васильев Артем Александрович
A22: 573 | B22: изменение ЮЛ | C22: 69210 | D22: стоп | S22: Васильев Артем Александрович
A23: 574 | B23: изменение ЮЛ | C23: 46755 | D23: стоп | S23: Васильев Артем Александрович
A24: 575 | B24: изменение ЮЛ | C24: 25020 | D24: стоп | S24: Васильев Артем Александрович
A25: 576 | B25: изменение ЮЛ | C25: 36365 | D25: стоп | S25: Васильев Артем Александрович
A26: 328 | C26: 116473.5 | D26: 110700 | S26: Иванова Мария Сергеевна
A27: 716 | B27: первая часть оплаты | C27: 18640 | D27: 18710 | S27: Соколова Анастасия Викторовна
A28: 716 | B28: вторая часть оплаты | C28: 3165 | D28: 2110 | S28: Соколова Анастасия Викторовна
A29: 613 | B29: первая часть оплаты | C29: в ноль | D29: стоп | S29: Васильев Артем Александрович
A30: 615 | B30: первая часть оплаты | C30: в ноль | D30: стоп | S30: Васильев Артем Александрович
A31: 617 | B31: первая часть оплаты | C31: в ноль | D31: стоп | S31: Васильев Артем Александрович
A32: 643 | B32: первая часть оплаты | C32: в ноль | D32: стоп | S32: Васильев Артем Александрович
A33: 318 | C33: 17950 | D33: 20590 | S33: Попова Екатерина Николаевна
A34: 603 | S34: Михайлов Андрей Сергеевич
A35: 461 | B35: первая часть оплаты | C35: 103230 | D35: 103230 | S35: Иванова Мария Сергеевна
A36: 461 | B36: вторая часть оплаты | C36: 27720 | D36: 27180 | S36: Иванова Мария Сергеевна
A37: 717 | D37: 34100 | S37: Попова Екатерина Николаевна
A38: 418 | C38: 160420 | D38: стоп | S38: Михайлов Андрей Сергеевич
A39: 456 | C39: 91240 | D39: стоп | S39: Михайлов Андрей Сергеевич
A40: 457 | C40: 104675 | D40: стоп | S40: Михайлов Андрей Сергеевич
...

Sheet prolongations
A1: id | B1: month | C1: AM
A2: 15 | B2: декабрь 2022 | C2: Иванова Мария Сергеевна
A3: 15 | B3: февраль 2023 | C3: Иванова Мария Сергеевна
A4: 15 | B4: март 2023 | C4: Иванова Мария Сергеевна
A5: 15 | B5: апрель 2023 | C5: Иванова Мария Сергеевна
A6: 15 | B6: июнь 2023 | C6: Иванова Мария Сергеевна
A7: 16 | B7: декабрь 2022 | C7: Иванова Мария Сергеевна
A8: 31 | B8: декабрь 2022 | C8: Васильев Артем Александрович
A9: 39 | B9: декабрь 2022 | C9: Иванова Мария Сергеевна
A10: 39 | B10: декабрь 2023 | C10: Попова Екатерина Николаевна
A11: 42 | B11: ноябрь 2022 | C11: Васильев Артем Александрович
A12: 45 | B12: декабрь 2022 | C12: Попова Екатерина Николаевна
A13: 45 | B13: декабрь 2023 | C13: Попова Екатерина Николаевна
... A478: 1015 | B478: ноябрь 2023 | C478: Смирнова Ольга Владимировна

Sheet financial data unpivot
A1: id | B1: Причина дубля | C1: Account | D1: Месяц | E1: Значение | F1: Значения числа | G1: Месяц окончания | H1: month (prolongations) | I1: Значение окончания | J1: Значение пролонгации1 | K1: Значение пролонгации2
A2: 42 | C2: Васильев Артем Александрович | D2: 44866 | E2: 36220 | F2: =IF(ISTEXT(Таблицаx_2[[#This Row],[Значение]]), 0, Таблицаx_2[[#This Row],[Значение]]) -> 36220 | G2: 44866 | H2: =IFERROR(VLOOKUP(Таблицаx_2[[#This Row],[id]],prolongations!A:C,2,)," ") -> ноябрь 2022 | I2: =IF(Таблицаx_2[[#This Row],[Месяц окончания]]=Таблицаx_2[[#This Row],[Месяц]],Таблицаx_2[[#This Row],[Значения числа]],0) -> 36220 | J2: =IF(AND(Таблицаx_2[[#This Row],[Месяц окончания]]=Таблицаx_2[[#This Row],[Месяц]],Таблицаx_2[[#This Row],[id]]=A3,EDATE(Таблицаx_2[[#This Row],[Месяц]],1)=D3),F3,0) -> 0 | K2: =IF(AND(Таблицаx_2[[#This Row],[Месяц окончания]]=Таблицаx_2[[#This Row],[Месяц]],Таблицаx_2[[#This Row],[id]]=A3,EDATE(Таблицаx_2[[#This Row],[Месяц]],2)=D3),F3,0) -> 0
A3: 657 | B3: первая часть оплаты | C3: Васильев Артем Александрович | D3: 44866 | E3: стоп | F3: =IF(ISTEXT(Таблицаx_2[[#This Row],[Значение]]), 0, Таблицаx_2[[#This Row],[Значение]]) -> 0 | G3: 44866 | H3: =IFERROR(VLOOKUP(Таблицаx_2[[#This Row],[id]],prolongations!A:C,2,)," ") -> ноябрь 2022 | I3: =IF(Таблицаx_2[[#This Row],[Месяц окончания]]=Таблицаx_2[[#This Row],[Месяц]],Таблицаx_2[[#This Row],[Значения числа]],0) -> 0 | J3: =IF(AND(Таблицаx_2[[#This Row],[Месяц окончания]]=Таблицаx_2[[#This Row],[Месяц]],Таблицаx_2[[#This Row],[id]]=A4,EDATE(Таблицаx_2[[#This Row],[Месяц]],1)=D4),F4,0) -> 0 | K3: =IF(AND(Таблицаx_2[[#This Row],[Месяц окончания]]=Таблицаx_2[[#This Row],[Месяц]],Таблицаx_2[[#This Row],[id]]=A4,EDATE(Таблицаx_2[[#This Row],[Месяц]],2)=D4),F4,0) -> 0
A4: 657 | B4: вторая часть оплаты | C4: Васильев Артем Александрович | D4: 44866 | E4: стоп | F4: =IF(ISTEXT(Таблицаx_2[[#This Row],[Значение]]), 0, Таблицаx_2[[#This Row],[Значение]]) -> 0 | G4: 44866 | H4: =IFERROR(VLOOKUP(Таблицаx_2[[#This Row],[id]],prolongations!A:C,2,)," ") -> ноябрь 2022 | I4: =IF(Таблицаx_2[[#This Row],[Месяц окончания]]=Таблицаx_2[[#This Row],[Месяц]],Таблицаx_2[[#This Row],[Значения числа]],0) -> 0 | J4: =IF(AND(Таблицаx_2[[#This Row],[Месяц окончания]]=Таблицаx_2[[#This Row],[Месяц]],Таблицаx_2[[#This Row],[id]]=A5,EDATE(Таблицаx_2[[#This Row],[Месяц]],1)=D5),F5,0) -> 0 | K4: =IF(AND(Таблицаx_2[[#This Row],[Месяц окончания]]=Таблицаx_2[[#This Row],[Месяц]],Таблицаx_2[[#This Row],[id]]=A5,EDATE(Таблицаx_2[[#This Row],[Месяц]],2)=D5),F5,0) -> 0
A5: 594 | C5: Васильев Артем Александрович | D5: 44866 | E5: стоп | F5: =IF(ISTEXT(Таблицаx_2[[#This Row],[Значение]]), 0, Таблицаx_2[[#This Row],[Значение]]) -> 0 | G5: 44866 | H5: =IFERROR(VLOOKUP(Таблицаx_2[[#This Row],[id]],prolongations!A:C,2,)," ") -> ноябрь 2022 | I5: =IF(Таблицаx_2[[#This Row],[Месяц окончания]]=Таблицаx_2[[#This Row],[Месяц]],Таблицаx_2[[#This Row],[Значения числа]],0) -> 0 | J5: =IF(AND(Таблицаx_2[[#This Row],[Месяц окончания]]=Таблицаx_2[[#This Row],[Месяц]],Таблицаx_2[[#This Row],[id]]=A6,EDATE(Таблицаx_2[[#This Row],[Месяц]],1)=D6),F6,0) -> 0 | K5: =IF(AND(Таблицаx_2[[#This Row],[Месяц окончания]]=Таблицаx_2[[#This Row],[Месяц]],Таблицаx_2[[#This Row],[id]]=A6,EDATE(Таблицаx_2[[#This Row],[Месяц]],2)=D6),F6,0) -> 0
A6: 665 | C6: Васильев Артем Александрович | D6: 44866 | E6: 10000 | F6: =IF(ISTEXT(Таблицаx_2[[#This Row],[Значение]]), 0, Таблицаx_2[[#This Row],[Значение]]) -> 10000 | G6: 44866 | H6: =IFERROR(VLOOKUP(Таблицаx_2[[#This Row],[id]],prolongations!A:C,2,)," ") -> ноябрь 2022 | I6: =IF(Таблицаx_2[[#This Row],[Месяц окончания]]=Таблицаx_2[[#This Row],[Месяц]],Таблицаx_2[[#This Row],[Значения числа]],0) -> 10000 | J6: =IF(AND(Таблицаx_2[[#This Row],[Месяц окончания]]=Таблицаx_2[[#This Row],[Месяц]],Таблицаx_2[[#This Row],[id]]=A7,EDATE(Таблицаx_2[[#This Row],[Месяц]],1)=D7),F7,0) -> 0 | K6: =IF(AND(Таблицаx_2[[#This Row],[Месяц окончания]]=Таблицаx_2[[#This Row],[Месяц]],Таблицаx_2[[#This Row],[id]]=A7,EDATE(Таблицаx_2[[#This Row],[Месяц]],2)=D7),F7,0) -> 0
A7: 637 | C7: Соколова Анастасия Викторовна | D7: 44866 | E7: 38045 | F7: =IF(ISTEXT(Таблицаx_2[[#This Row],[Значение]]), 0, Таблицаx_2[[#This Row],[Значение]]) -> 38045 | G7: 44866 | H7: =IFERROR(VLOOKUP(Таблицаx_2[[#This Row],[id]],prolongations!A:C,2,)," ") -> ноябрь 2022 | I7: =IF(Таблицаx_2[[#This Row],[Месяц окончания]]=Таблицаx_2[[#This Row],[Месяц]],Таблицаx_2[[#This Row],[Значения числа]],0) -> 38045 | J7: =IF(AND(Таблицаx_2[[#This Row],[Месяц окончания]]=Таблицаx_2[[#This Row],[Месяц]],Таблицаx_2[[#This Row],[id]]=A8,EDATE(Таблицаx_2[[#This Row],[Месяц]],1)=D8),F8,0) -> 0 | K7: =IF(AND(Таблицаx_2[[#This Row],[Месяц окончания]]=Таблицаx_2[[#This Row],[Месяц]],Таблицаx_2[[#This Row],[id]]=A8,EDATE(Таблицаx_2[[#This Row],[Месяц]],2)=D8),F8,0) -> 0
A8: 578 | C8: Попова Екатерина Николаевна | D8: 44866 | E8: 82800 | F8: =IF(ISTEXT(Таблицаx_2[[#This Row],[Значение]]), 0, Таблицаx_2[[#This Row],[Значение]]) -> 82800 | G8: 44866 | H8: =IFERROR(VLOOKUP(Таблицаx_2[[#This Row],[id]],prolongations!A:C,2,)," ") -> ноябрь 2022 | I8: =IF(Таблицаx_2[[#This Row],[Месяц окончания]]=Таблицаx_2[[#This Row],[Месяц]],Таблицаx_2[[#This Row],[Значения числа]],0) -> 82800 | J8: =IF(AND(Таблицаx_2[[#This Row],[Месяц окончания]]=Таблицаx_2[[#This Row],[Месяц]],Таблицаx_2[[#This Row],[id]]=A9,EDATE(Таблицаx_2[[#This Row],[Месяц]],1)=D9),F9,0) -> 0 | K8: =IF(AND(Таблицаx_2[[#This Row],[Месяц окончания]]=Таблицаx_2[[#This Row],[Месяц]],Таблицаx_2[[#This Row],[id]]=A9,EDATE(Таблицаx_2[[#This Row],[Месяц]],2)=D9),F9,0) -> 0
A9: 579 | C9: Васильев Артем Александрович | D9: 44866 | E9: в ноль | F9: =IF(ISTEXT(Таблицаx_2[[#This Row],[Значение]]), 0, Таблицаx_2[[#This Row],[Значение]]) -> 0 | G9: 44866 | H9: =IFERROR(VLOOKUP(Таблицаx_2[[#This Row],[id]],prolongations!A:C,2,)," ") -> ноябрь 2022 | I9: =IF(Таблицаx_2[[#This Row],[Месяц окончания]]=Таблицаx_2[[#This Row],[Месяц]],Таблицаx_2[[#This Row],[Значения числа]],0) -> 0 | J9: =IF(AND(Таблицаx_2[[#This Row],[Месяц окончания]]=Таблицаx_2[[#This Row],[Месяц]],Таблицаx_2[[#This Row],[id]]=A10,EDATE(Таблицаx_2[[#This Row],[Месяц]],1)=D10),F10,0) -> 0 | K9: =IF(AND(Таблицаx_2[[#This Row],[Месяц окончания]]=Таблицаx_2[[#This Row],[Месяц]],Таблицаx_2[[#This Row],[id]]=A10,EDATE(Таблицаx_2[[#This Row],[Месяц]],2)=D10),F10,0) -> 0
A10: 592 | B10: первая часть оплаты | C10: Васильев Артем Александрович | D10: 44866 | E10: 92302 | F10: =IF(ISTEXT(Таблицаx_2[[#This Row],[Значение]]), 0, Таблицаx_2[[#This Row],[Значение]]) -> 92302 | G10: 44866 | H10: =IFERROR(VLOOKUP(Таблицаx_2[[#This Row],[id]],prolongations!A:C,2,)," ") -> ноябрь 2022 | I10: =IF(Таблицаx_2[[#This Row],[Месяц окончания]]=Таблицаx_2[[#This Row],[Месяц]],Таблицаx_2[[#This Row],[Значения числа]],0) -> 92302 | J10: =IF(AND(Таблицаx_2[[#This Row],[Месяц окончания]]=Таблицаx_2[[#This Row],[Месяц]],Таблицаx_2[[#This Row],[id]]=A11,EDATE(Таблицаx_2[[#This Row],[Месяц]],1)=D11),F11,0) -> 0 | K10: =IF(AND(Таблицаx_2[[#This Row],[Месяц окончания]]=Таблицаx_2[[#This Row],[Месяц]],Таблицаx_2[[#This Row],[id]]=A11,EDATE(Таблицаx_2[[#This Row],[Месяц]],2)=D11),F11,0) -> 0
A11: 592 | B11: вторая часть оплаты | C11: Васильев Артем Александрович | D11: 44866 | E11: 12340 | F11: =IF(ISTEXT(Таблицаx_2[[#This Row],[Значение]]), 0, Таблицаx_2[[#This Row],[Значение]]) -> 12340 | G11: 44866 | H11: =IFERROR(VLOOKUP(Таблицаx_2[[#This Row],[id]],prolongations!A:C,2,)," ") -> ноябрь 2022 | I11: =IF(Таблицаx_2[[#This Row],[Месяц окончания]]=Таблицаx_2[[#This Row],[Месяц]],Таблицаx_2[[#This Row],[Значения числа]],0) -> 12340 | J11: =IF(AND(Таблицаx_2[[#This Row],[Месяц окончания]]=Таблицаx_2[[#This Row],[Месяц]],Таблицаx_2[[#This Row],[id]]=A12,EDATE(Таблицаx_2[[#This Row],[Месяц]],1)=D12),F12,0) -> 0 | K11: =IF(AND(Таблицаx_2[[#This Row],[Месяц окончания]]=Таблицаx_2[[#This Row],[Месяц]],Таблицаx_2[[#This Row],[id]]=A12,EDATE(Таблицаx_2[[#This Row],[Месяц]],2)=D12),F12,0) -> 0
A12: 666 | C12: Васильев Артем Александрович | D12: 44866 | E12: 110000 | F12: =IF(ISTEXT(Таблицаx_2[[#This Row],[Значение]]), 0, Таблицаx_2[[#This Row],[Значение]]) -> 110000 | G12: 44866 | H12: =IFERROR(VLOOKUP(Таблицаx_2[[#This Row],[id]],prolongations!A:C,2,)," ") -> ноябрь 2022 | I12: =IF(Таблицаx_2[[#This Row],[Месяц окончания]]=Таблицаx_2[[#This Row],[Месяц]],Таблицаx_2[[#This Row],[Значения числа]],0) -> 110000 | J12: =IF(AND(Таблицаx_2[[#This Row],[Месяц окончания]]=Таблицаx_2[[#This Row],[Месяц]],Таблицаx_2[[#This Row],[id]]=A13,EDATE(Таблицаx_2[[#This Row],[Месяц]],1)=D13),F13,0) -> 0 | K12: =IF(AND(Таблицаx_2[[#This Row],[Месяц окончания]]=Таблицаx_2[[#This Row],[Месяц]],Таблицаx_2[[#This Row],[id]]=A13,EDATE(Таблицаx_2[[#This Row],[Месяц]],2)=D13),F13,0) -> 0
A13: 620 | C13: Васильев Артем Александрович | D13: 44866 | E13: в ноль | F13: =IF(ISTEXT(Таблицаx_2[[#This Row],[Значение]]), 0, Таблицаx_2[[#This Row],[Значение]]) -> 0 | G13: 44866 | H13: =IFERROR(VLOOKUP(Таблицаx_2[[#This Row],[id]],prolongations!A:C,2,)," ") -> ноябрь 2022 | I13: =IF(Таблицаx_2[[#This Row],[Месяц окончания]]=Таблицаx_2[[#This Row],[Месяц]],Таблицаx_2[[#This Row],[Значения числа]],0) -> 0 | J13: =IF(AND(Таблицаx_2[[#This Row],[Месяц окончания]]=Таблицаx_2[[#This Row],[Месяц]],Таблицаx_2[[#This Row],[id]]=A14,EDATE(Таблицаx_2[[#This Row],[Месяц]],1)=D14),F14,0) -> 0 | K13: =IF(AND(Таблицаx_2[[#This Row],[Месяц окончания]]=Таблицаx_2[[#This Row],[Месяц]],Таблицаx_2[[#This Row],[id]]=A14,EDATE(Таблицаx_2[[#This Row],[Месяц]],2)=D14),F14,0) -> 0
A14: 704 | B14: первая часть оплаты | C14: Михайлов Андрей Сергеевич | D14: 44866 | E14: 35365 | F14: =IF(ISTEXT(Таблицаx_2[[#This Row],[Значение]]), 0, Таблицаx_2[[#This Row],[Значение]]) -> 35365 | G14: 44866 | H14: =IFERROR(VLOOKUP(Таблицаx_2[[#This Row],[id]],prolongations!A:C,2,)," ") -> ноябрь 2022 | I14: =IF(Таблицаx_2[[#This Row],[Месяц окончания]]=Таблицаx_2[[#This Row],[Месяц]],Таблицаx_2[[#This Row],[Значения числа]],0) -> 35365 | J14: =IF(AND(Таблицаx_2[[#This Row],[Месяц окончания]]=Таблицаx_2[[#This Row],[Месяц]],Таблицаx_2[[#This Row],[id]]=A15,EDATE(Таблицаx_2[[#This Row],[Месяц]],1)=D15),F15,0) -> 0 | K14: =IF(AND(Таблицаx_2[[#This Row],[Месяц окончания]]=Таблицаx_2[[#This Row],[Месяц]],Таблицаx_2[[#This Row],[id]]=A15,EDATE(Таблицаx_2[[#This Row],[Месяц]],2)=D15),F15,0) -> 0
A15: 704 | B15: вторая часть оплаты | C15: Михайлов Андрей Сергеевич | D15: 44866 | E15: 945 | F15: =IF(ISTEXT(Таблицаx_2[[#This Row],[Значение]]), 0, Таблицаx_2[[#This Row],[Значение]]) -> 945 | G15: 44866 | H15: =IFERROR(VLOOKUP(Таблицаx_2[[#This Row],[id]],prolongations!A:C,2,)," ") -> ноябрь 2022 | I15: =IF(Таблицаx_2[[#This Row],[Месяц окончания]]=Таблицаx_2[[#This Row],[Месяц]],Таблицаx_2[[#This Row],[Значения числа]],0) -> 945 | J15: =IF(AND(Таблицаx_2[[#This Row],[Месяц окончания]]=Таблицаx_2[[#This Row],[Месяц]],Таблицаx_2[[#This Row],[id]]=A16,EDATE(Таблицаx_2[[#This Row],[Месяц]],1)=D16),F16,0) -> 0 | K15: =IF(AND(Таблицаx_2[[#This Row],[Месяц окончания]]=Таблицаx_2[[#This Row],[Месяц]],Таблицаx_2[[#This Row],[id]]=A16,EDATE(Таблицаx_2[[#This Row],[Месяц]],2)=D16),F16,0) -> 0
A16: 704 | B16: вторая часть оплаты | C16: Михайлов Андрей Сергеевич | D16: 44866 | E16: 4715 | F16: =IF(ISTEXT(Таблицаx_2[[#This Row],[Значение]]), 0, Таблицаx_2[[#This Row],[Значение]]) -> 4715 | G16: 44866 | H16: =IFERROR(VLOOKUP(Таблицаx_2[[#This Row],[id]],prolongations!A:C,2,)," ") -> ноябрь 2022 | I16: =IF(Таблицаx_2[[#This Row],[Месяц окончания]]=Таблицаx_2[[#This Row],[Месяц]],Таблицаx_2[[#This Row],[Значения числа]],0) -> 4715 | J16: =IF(AND(Таблицаx_2[[#This Row],[Месяц окончания]]=Таблицаx_2[[#This Row],[Месяц]],Таблицаx_2[[#This Row],[id]]=A17,EDATE(Таблицаx_2[[#This Row],[Месяц]],1)=D17),F17,0) -> 0 | K16: =IF(AND(Таблицаx_2[[#This Row],[Месяц окончания]]=Таблицаx_2[[#This Row],[Месяц]],Таблицаx_2[[#This Row],[id]]=A17,EDATE(Таблицаx_2[[#This Row],[Месяц]],2)=D17),F17,0) -> 0
A17: 379 | C17: Иванова Мария Сергеевна | D17: 44866 | E17: 55195 | F17: =IF(ISTEXT(Таблицаx_2[[#This Row],[Значение]]), 0, Таблицаx_2[[#This Row],[Значение]]) -> 55195 | G17: 44896 | H17: =IFERROR(VLOOKUP(Таблицаx_2[[#This Row],[id]],prolongations!A:C,2,)," ") -> декабрь 2022 | I17: =IF(Таблицаx_2[[#This Row],[Месяц окончания]]=Таблицаx_2[[#This Row],[Месяц]],Таблицаx_2[[#This Row],[Значения числа]],0) -> 0 | J17: =IF(AND(Таблицаx_2[[#This Row],[Месяц окончания]]=Таблицаx_2[[#This Row],[Месяц]],Таблицаx_2[[#This Row],[id]]=A18,EDATE(Таблицаx_2[[#This Row],[Месяц]],1)=D18),F18,0) -> 0 | K17: =IF(AND(Таблицаx_2[[#This Row],[Месяц окончания]]=Таблицаx_2[[#This Row],[Месяц]],Таблицаx_2[[#This Row],[id]]=A18,EDATE(Таблицаx_2[[#This Row],[Месяц]],2)=D18),F18,0) -> 0
A18: 379 | C18: Иванова Мария Сергеевна | D18: 44896 | E18: 55195 | F18: =IF(ISTEXT(Таблицаx_2[[#This Row],[Значение]]), 0, Таблицаx_2[[#This Row],[Значение]]) -> 55195 | G18: 44896 | H18: =IFERROR(VLOOKUP(Таблицаx_2[[#This Row],[id]],prolongations!A:C,2,)," ") -> декабрь 2022 | I18: =IF(Таблицаx_2[[#This Row],[Месяц окончания]]=Таблицаx_2[[#This Row],[Месяц]],Таблицаx_2[[#This Row],[Значения числа]],0) -> 55195 | J18: =IF(AND(Таблицаx_2[[#This Row],[Месяц окончания]]=Таблицаx_2[[#This Row],[Месяц]],Таблицаx_2[[#This Row],[id]]=A19,EDATE(Таблицаx_2[[#This Row],[Месяц]],1)=D19),F19,0) -> 0 | K18: =IF(AND(Таблицаx_2[[#This Row],[Месяц окончания]]=Таблицаx_2[[#This Row],[Месяц]],Таблицаx_2[[#This Row],[id]]=A19,EDATE(Таблицаx_2[[#This Row],[Месяц]],2)=D19),F19,0) -> 0
A19: 31 | C19: Васильев Артем Александрович | D19: 44866 | E19: 55100 | F19: =IF(ISTEXT(Таблицаx_2[[#This Row],[Значение]]), 0, Таблицаx_2[[#This Row],[Значение]]) -> 55100 | G19: 44896 | H19: =IFERROR(VLOOKUP(Таблицаx_2[[#This Row],[id]],prolongations!A:C,2,)," ") -> декабрь 2022 | I19: =IF(Таблицаx_2[[#This Row],[Месяц окончания]]=Таблицаx_2[[#This Row],[Месяц]],Таблицаx_2[[#This Row],[Значения числа]],0) -> 0 | J19: =IF(AND(Таблицаx_2[[#This Row],[Месяц окончания]]=Таблицаx_2[[#This Row],[Месяц]],Таблицаx_2[[#This Row],[id]]=A20,EDATE(Таблицаx_2[[#This Row],[Месяц]],1)=D20),F20,0) -> 0 | K19: =IF(AND(Таблицаx_2[[#This Row],[Месяц окончания]]=Таблицаx_2[[#This Row],[Месяц]],Таблицаx_2[[#This Row],[id]]=A20,EDATE(Таблицаx_2[[#This Row],[Месяц]],2)=D20),F20,0) -> 0
A20: 31 | C20: Васильев Артем Александрович | D20: 44896 | E20: 55100 | F20: =IF(ISTEXT(Таблицаx_2[[#This Row],[Значение]]), 0, Таблицаx_2[[#This Row],[Значение]]) -> 55100 | G20: 44896 | H20: =IFERROR(VLOOKUP(Таблицаx_2[[#This Row],[id]],prolongations!A:C,2,)," ") -> декабрь 2022 | I20: =IF(Таблицаx_2[[#This Row],[Месяц окончания]]=Таблицаx_2[[#This Row],[Месяц]],Таблицаx_2[[#This Row],[Значения числа]],0) -> 55100 | J20: =IF(AND(Таблицаx_2[[#This Row],[Месяц окончания]]=Таблицаx_2[[#This Row],[Месяц]],Таблицаx_2[[#This Row],[id]]=A21,EDATE(Таблицаx_2[[#This Row],[Месяц]],1)=D21),F21,0) -> 0 | K20: =IF(AND(Таблицаx_2[[#This Row],[Месяц окончания]]=Таблицаx_2[[#This Row],[Месяц]],Таблицаx_2[[#This Row],[id]]=A21,EDATE(Таблицаx_2[[#This Row],[Месяц]],2)=D21),F21,0) -> 44775
A21: 31 | C21: Васильев Артем Александрович | D21: 44958 | E21: 44775 | F21: =IF(ISTEXT(Таблицаx_2[[#This Row],[Значение]]), 0, Таблицаx_2[[#This Row],[Значение]]) -> 44775 | G21: 44896 | H21: =IFERROR(VLOOKUP(Таблицаx_2[[#This Row],[id]],prolongations!A:C,2,)," ") -> декабрь 2022 | I21: =IF(Таблицаx_2[[#This Row],[Месяц окончания]]=Таблицаx_2[[#This Row],[Месяц]],Таблицаx_2[[#This Row],[Значения числа]],0) -> 0 | J21: =IF(AND(Таблицаx_2[[#This Row],[Месяц окончания]]=Таблицаx_2[[#This Row],[Месяц]],Таблицаx_2[[#This Row],[id]]=A22,EDATE(Таблицаx_2[[#This Row],[Месяц]],1)=D22),F22,0) -> 0 | K21: =IF(AND(Таблицаx_2[[#This Row],[Месяц окончания]]=Таблицаx_2[[#This Row],[Месяц]],Таблицаx_2[[#This Row],[id]]=A22,EDATE(Таблицаx_2[[#This Row],[Месяц]],2)=D22),F22,0) -> 0
A22: 31 | C22: Васильев Артем Александрович | D22: 44986 | E22: 44775 | F22: =IF(ISTEXT(Таблицаx_2[[#This Row],[Значение]]), 0, Таблицаx_2[[#This Row],[Значение]]) -> 44775 | G22: 44896 | H22: =IFERROR(VLOOKUP(Таблицаx_2[[#This Row],[id]],prolongations!A:C,2,)," ") -> декабрь 2022 | I22: =IF(Таблицаx_2[[#This Row],[Месяц окончания]]=Таблицаx_2[[#This Row],[Месяц]],Таблицаx_2[[#This Row],[Значения числа]],0) -> 0 | J22: =IF(AND(Таблицаx_2[[#This Row],[Месяц окончания]]=Таблицаx_2[[#This Row],[Месяц]],Таблицаx_2[[#This Row],[id]]=A23,EDATE(Таблицаx_2[[#This Row],[Месяц]],1)=D23),F23,0) -> 0 | K22: =IF(AND(Таблицаx_2[[#This Row],[Месяц окончания]]=Таблицаx_2[[#This Row],[Месяц]],Таблицаx_2[[#This Row],[id]]=A23,EDATE(Таблицаx_2[[#This Row],[Месяц]],2)=D23),F23,0) -> 0
A23: 31 | C23: Васильев Артем Александрович | D23: 45017 | E23: 44775 | F23: =IF(ISTEXT(Таблицаx_2[[#This Row],[Значение]]), 0, Таблицаx_2[[#This Row],[Значение]]) -> 44775 | G23: 44896 | H23: =IFERROR(VLOOKUP(Таблицаx_2[[#This Row],[id]],prolongations!A:C,2,)," ") -> декабрь 2022 | I23: =IF(Таблицаx_2[[#This Row],[Месяц окончания]]=Таблицаx_2[[#This Row],[Месяц]],Таблицаx_2[[#This Row],[Значения числа]],0) -> 0 | J23: =IF(AND(Таблицаx_2[[#This Row],[Месяц окончания]]=Таблицаx_2[[#This Row],[Месяц]],Таблицаx_2[[#This Row],[id]]=A24,EDATE(Таблицаx_2[[#This Row],[Месяц]],1)=D24),F24,0) -> 0 | K23: =IF(AND(Таблицаx_2[[#This Row],[Месяц окончания]]=Таблицаx_2[[#This Row],[Месяц]],Таблицаx_2[[#This Row],[id]]=A24,EDATE(Таблицаx_2[[#This Row],[Месяц]],2)=D24),F24,0) -> 0
A24: 31 | C24: Васильев Артем Александрович | D24: 45047 | E24: 44775 | F24: =IF(ISTEXT(Таблицаx_2[[#This Row],[Значение]]), 0, Таблицаx_2[[#This Row],[Значение]]) -> 44775 | G24: 44896 | H24: =IFERROR(VLOOKUP(Таблицаx_2[[#This Row],[id]],prolongations!A:C,2,)," ") -> декабрь 2022 | I24: =IF(Таблицаx_2[[#This Row],[Месяц окончания]]=Таблицаx_2[[#This Row],[Месяц]],Таблицаx_2[[#This Row],[Значения числа]],0) -> 0 | J24: =IF(AND(Таблицаx_2[[#This Row],[Месяц окончания]]=Таблицаx_2[[#This Row],[Месяц]],Таблицаx_2[[#This Row],[id]]=A25,EDATE(Таблицаx_2[[#This Row],[Месяц]],1)=D25),F25,0) -> 0 | K24: =IF(AND(Таблицаx_2[[#This Row],[Месяц окончания]]=Таблицаx_2[[#This Row],[Месяц]],Таблицаx_2[[#This Row],[id]]=A25,EDATE(Таблицаx_2[[#This Row],[Месяц]],2)=D25),F25,0) -> 0
A25: 31 | C25: Васильев Артем Александрович | D25: 45078 | E25: 44775 | F25: =IF(ISTEXT(Таблицаx_2[[#This Row],[Значение]]), 0, Таблицаx_2[[#This Row],[Значение]]) -> 44775 | G25: 44896 | H25: =IFERROR(VLOOKUP(Таблицаx_2[[#This Row],[id]],prolongations!A:C,2,)," ") -> декабрь 2022 | I25: =IF(Таблицаx_2[[#This Row],[Месяц окончания]]=Таблицаx_2[[#This Row],[Месяц]],Таблицаx_2[[#This Row],[Значения числа]],0) -> 0 | J25: =IF(AND(Таблицаx_2[[#This Row],[Месяц окончания]]=Таблицаx_2[[#This Row],[Месяц]],Таблицаx_2[[#This Row],[id]]=A26,EDATE(Таблицаx_2[[#This Row],[Месяц]],1)=D26),F26,0) -> 0 | K25: =IF(AND(Таблицаx_2[[#This Row],[Месяц окончания]]=Таблицаx_2[[#This Row],[Месяц]],Таблицаx_2[[#This Row],[id]]=A26,EDATE(Таблицаx_2[[#This Row],[Месяц]],2)=D26),F26,0) -> 0
A26: 31 | C26: Васильев Артем Александрович | D26: 45108 | E26: 44775 | F26: =IF(ISTEXT(Таблицаx_2[[#This Row],[Значение]]), 0, Таблицаx_2[[#This Row],[Значение]]) -> 44775 | G26: 44896 | H26: =IFERROR(VLOOKUP(Таблицаx_2[[#This Row],[id]],prolongations!A:C,2,)," ") -> декабрь 2022 | I26: =IF(Таблицаx_2[[#This Row],[Месяц окончания]]=Таблицаx_2[[#This Row],[Месяц]],Таблицаx_2[[#This Row],[Значения числа]],0) -> 0 | J26: =IF(AND(Таблицаx_2[[#This Row],[Месяц окончания]]=Таблицаx_2[[#This Row],[Месяц]],Таблицаx_2[[#This Row],[id]]=A27,EDATE(Таблицаx_2[[#This Row],[Месяц]],1)=D27),F27,0) -> 0 | K26: =IF(AND(Таблицаx_2[[#This Row],[Месяц окончания]]=Таблицаx_2[[#This Row],[Месяц]],Таблицаx_2[[#This Row],[id]]=A27,EDATE(Таблицаx_2[[#This Row],[Месяц]],2)=D27),F27,0) -> 0
A27: 31 | C27: Васильев Артем Александрович | D27: 45139 | E27: 44775 | F27: =IF(ISTEXT(Таблицаx_2[[#This Row],[Значение]]), 0, Таблицаx_2[[#This Row],[Значение]]) -> 44775 | G27: 44896 | H27: =IFERROR(VLOOKUP(Таблицаx_2[[#This Row],[id]],prolongations!A:C,2,)," ") -> декабрь 2022 | I27: =IF(Таблицаx_2[[#This Row],[Месяц окончания]]=Таблицаx_2[[#This Row],[Месяц]],Таблицаx_2[[#This Row],[Значения числа]],0) -> 0 | J27: =IF(AND(Таблицаx_2[[#This Row],[Месяц окончания]]=Таблицаx_2[[#This Row],[Месяц]],Таблицаx_2[[#This Row],[id]]=A28,EDATE(Таблицаx_2[[#This Row],[Месяц]],1)=D28),F28,0) -> 0 | K27: =IF(AND(Таблицаx_2[[#This Row],[Месяц окончания]]=Таблицаx_2[[#This Row],[Месяц]],Таблицаx_2[[#This Row],[id]]=A28,EDATE(Таблицаx_2[[#This Row],[Месяц]],2)=D28),F28,0) -> 0
A28: 31 | C28: Васильев Артем Александрович | D28: 45170 | E28: 44775 | F28: =IF(ISTEXT(Таблицаx_2[[#This Row],[Значение]]), 0, Таблицаx_2[[#This Row],[Значение]]) -> 44775 | G28: 44896 | H28: =IFERROR(VLOOKUP(Таблицаx_2[[#This Row],[id]],prolongations!A:C,2,)," ") -> декабрь 2022 | I28: =IF(Таблицаx_2[[#This Row],[Месяц окончания]]=Таблицаx_2[[#This Row],[Месяц]],Таблицаx_2[[#This Row],[Значения числа]],0) -> 0 | J28: =IF(AND(Таблицаx_2[[#This Row],[Месяц окончания]]=Таблицаx_2[[#This Row],[Месяц]],Таблицаx_2[[#This Row],[id]]=A29,EDATE(Таблицаx_2[[#This Row],[Месяц]],1)=D29),F29,0) -> 0 | K28: =IF(AND(Таблицаx_2[[#This Row],[Месяц окончания]]=Таблицаx_2[[#This Row],[Месяц]],Таблицаx_2[[#This Row],[id]]=A29,EDATE(Таблицаx_2[[#This Row],[Месяц]],2)=D29),F29,0) -> 0
... A33: 31 | C33: Васильев Артем Александрович | D33: 45323 | E33: 46200 | F33: =IF(ISTEXT(Таблицаx_2[[#This Row],[Значение]]), 0, Таблицаx_2[[#This Row],[Значение]]) -> 46200 | G33: 44896 | H33: =IFERROR(VLOOKUP(Таблицаx_2[[#This Row],[id]],prolongations!A:C,2,)," ") -> декабрь 2022 | I33: =IF(Таблицаx_2[[#This Row],[Месяц окончания]]=Таблицаx_2[[#This Row],[Месяц]],Таблицаx_2[[#This Row],[Значения числа]],0) -> 0 | J33: =IF(AND(Таблицаx_2[[#This Row],[Месяц окончания]]=Таблицаx_2[[#This Row],[Месяц]],Таблицаx_2[[#This Row],[id]]=A34,EDATE(Таблицаx_2[[#This Row],[Месяц]],1)=D34),F34,0) -> 0 | K33: =IF(AND(Таблицаx_2[[#This Row],[Месяц окончания]]=Таблицаx_2[[#This Row],[Месяц]],Таблицаx_2[[#This Row],[id]]=A34,EDATE(Таблицаx_2[[#This Row],[Месяц]],2)=D34),F34,0) -> 0
A34: 572 | B34: изменение ЮЛ | C34: Васильев Артем Александрович | D34: 44866 | E34: 56200 | F34: =IF(ISTEXT(Таблицаx_2[[#This Row],[Значение]]), 0, Таблицаx_2[[#This Row],[Значение]]) -> 56200 | G34: 44896 | H34: =IFERROR(VLOOKUP(Таблицаx_2[[#This Row],[id]],prolongations!A:C,2,)," ") -> декабрь 2022 | I34: =IF(Таблицаx_2[[#This Row],[Месяц окончания]]=Таблицаx_2[[#This Row],[Месяц]],Таблицаx_2[[#This Row],[Значения числа]],0) -> 0 | J34: =IF(AND(Таблицаx_2[[#This Row],[Месяц окончания]]=Таблицаx_2[[#This Row],[Месяц]],Таблицаx_2[[#This Row],[id]]=A35,EDATE(Таблицаx_2[[#This Row],[Месяц]],1)=D35),F35,0) -> 0 | K34: =IF(AND(Таблицаx_2[[#This Row],[Месяц окончания]]=Таблицаx_2[[#This Row],[Месяц]],Таблицаx_2[[#This Row],[id]]=A35,EDATE(Таблицаx_2[[#This Row],[Месяц]],2)=D35),F35,0) -> 0
A35: 572 | B35: изменение ЮЛ | C35: Васильев Артем Александрович | D35: 44896 | E35: стоп | F35: =IF(ISTEXT(Таблицаx_2[[#This Row],[Значение]]), 0, Таблицаx_2[[#This Row],[Значение]]) -> 0 | G35: 44896 | H35: =IFERROR(VLOOKUP(Таблицаx_2[[#This Row],[id]],prolongations!A:C,2,)," ") -> декабрь 2022 | I35: =IF(Таблицаx_2[[#This Row],[Месяц окончания]]=Таблицаx_2[[#This Row],[Месяц]],Таблицаx_2[[#This Row],[Значения числа]],0) -> 0 | J35: =IF(AND(Таблицаx_2[[#This Row],[Месяц окончания]]=Таблицаx_2[[#This Row],[Месяц]],Таблицаx_2[[#This Row],[id]]=A36,EDATE(Таблицаx_2[[#This Row],[Месяц]],1)=D36),F36,0) -> 0 | K35: =IF(AND(Таблицаx_2[[#This Row],[Месяц окончания]]=Таблицаx_2[[#This Row],[Месяц]],Таблицаx_2[[#This Row],[id]]=A36,EDATE(Таблицаx_2[[#This Row],[Месяц]],2)=D36),F36,0) -> 0
A36: 573 | B36: изменение ЮЛ | C36: Васильев Артем Александрович | D36: 44866 | E36: 69210 | F36: =IF(ISTEXT(Таблицаx_2[[#This Row],[Значение]]), 0, Таблицаx_2[[#This Row],[Значение]]) -> 69210 | G36: 44896 | H36: =IFERROR(VLOOKUP(Таблицаx_2[[#This Row],[id]],prolongations!A:C,2,)," ") -> декабрь 2022 | I36: =IF(Таблицаx_2[[#This Row],[Месяц окончания]]=Таблицаx_2[[#This Row],[Месяц]],Таблицаx_2[[#This Row],[Значения числа]],0) -> 0 | J36: =IF(AND(Таблицаx_2[[#This Row],[Месяц окончания]]=Таблицаx_2[[#This Row],[Месяц]],Таблицаx_2[[#This Row],[id]]=A37,EDATE(Таблицаx_2[[#This Row],[Месяц]],1)=D37),F37,0) -> 0 | K36: =IF(AND(Таблицаx_2[[#This Row],[Месяц окончания]]=Таблицаx_2[[#This Row],[Месяц]],Таблицаx_2[[#This Row],[id]]=A37,EDATE(Таблицаx_2[[#This Row],[Месяц]],2)=D37),F37,0) -> 0
A37: 573 | B37: изменение ЮЛ | C37: Васильев Артем Александрович | D37: 44896 | E37: стоп | F37: =IF(ISTEXT(Таблицаx_2[[#This Row],[Значение]]), 0, Таблицаx_2[[#This Row],[Значение]]) -> 0 | G37: 44896 | H37: =IFERROR(VLOOKUP(Таблицаx_2[[#This Row],[id]],prolongations!A:C,2,)," ") -> декабрь 2022 | I37: =IF(Таблицаx_2[[#This Row],[Месяц окончания]]=Таблицаx_2[[#This Row],[Месяц]],Таблицаx_2[[#This Row],[Значения числа]],0) -> 0 | J37: =IF(AND(Таблицаx_2[[#This Row],[Месяц окончания]]=Таблицаx_2[[#This Row],[Месяц]],Таблицаx_2[[#This Row],[id]]=A38,EDATE(Таблицаx_2[[#This Row],[Месяц]],1)=D38),F38,0) -> 0 | K37: =IF(AND(Таблицаx_2[[#This Row],[Месяц окончания]]=Таблицаx_2[[#This Row],[Месяц]],Таблицаx_2[[#This Row],[id]]=A38,EDATE(Таблицаx_2[[#This Row],[Месяц]],2)=D38),F38,0) -> 0
A38: 574 | B38: изменение ЮЛ | C38: Васильев Артем Александрович | D38: 44866 | E38: 46755 | F38: =IF(ISTEXT(Таблицаx_2[[#This Row],[Значение]]), 0, Таблицаx_2[[#This Row],[Значение]]) -> 46755 | G38: 44896 | H38: =IFERROR(VLOOKUP(Таблицаx_2[[#This Row],[id]],prolongations!A:C,2,)," ") -> декабрь 2022 | I38: =IF(Таблицаx_2[[#This Row],[Месяц окончания]]=Таблицаx_2[[#This Row],[Месяц]],Таблицаx_2[[#This Row],[Значения числа]],0) -> 0 | J38: =IF(AND(Таблицаx_2[[#This Row],[Месяц окончания]]=Таблицаx_2[[#This Row],[Месяц]],Таблицаx_2[[#This Row],[id]]=A39,EDATE(Таблицаx_2[[#This Row],[Месяц]],1)=D39),F39,0) -> 0 | K38: =IF(AND(Таблицаx_2[[#This Row],[Месяц окончания]]=Таблицаx_2[[#This Row],[Месяц]],Таблицаx_2[[#This Row],[id]]=A39,EDATE(Таблицаx_2[[#This Row],[Месяц]],2)=D39),F39,0) -> 0
A39: 574 | B39: изменение ЮЛ | C39: Васильев Артем Александрович | D39: 44896 | E39: стоп | F39: =IF(ISTEXT(Таблицаx_2[[#This Row],[Значение]]), 0, Таблицаx_2[[#This Row],[Значение]]) -> 0 | G39: 44896 | H39: =IFERROR(VLOOKUP(Таблицаx_2[[#This Row],[id]],prolongations!A:C,2,)," ") -> декабрь 2022 | I39: =IF(Таблицаx_2[[#This Row],[Месяц окончания]]=Таблицаx_2[[#This Row],[Месяц]],Таблицаx_2[[#This Row],[Значения числа]],0) -> 0 | J39: =IF(AND(Таблицаx_2[[#This Row],[Месяц окончания]]=Таблицаx_2[[#This Row],[Месяц]],Таблицаx_2[[#This Row],[id]]=A40,EDATE(Таблицаx_2[[#This Row],[Месяц]],1)=D40),F40,0) -> 0 | K39: =IF(AND(Таблицаx_2[[#This Row],[Месяц окончания]]=Таблицаx_2[[#This Row],[Месяц]],Таблицаx_2[[#This Row],[id]]=A40,EDATE(Таблицаx_2[[#This Row],[Месяц]],2)=D40),F40,0) -> 0
A40: 575 | B40: изменение ЮЛ | C40: Васильев Артем Александрович | D40: 44866 | E40: 25020 | F40: =IF(ISTEXT(Таблицаx_2[[#This Row],[Значение]]), 0, Таблицаx_2[[#This Row],[Значение]]) -> 25020 | G40: 44896 | H40: =IFERROR(VLOOKUP(Таблицаx_2[[#This Row],[id]],prolongations!A:C,2,)," ") -> декабрь 2022 | I40: =IF(Таблицаx_2[[#This Row],[Месяц окончания]]=Таблицаx_2[[#This Row],[Месяц]],Таблицаx_2[[#This Row],[Значения числа]],0) -> 0 | J40: =IF(AND(Таблицаx_2[[#This Row],[Месяц окончания]]=Таблицаx_2[[#This Row],[Месяц]],Таблицаx_2[[#This Row],[id]]=A41,EDATE(Таблицаx_2[[#This Row],[Месяц]],1)=D41),F41,0) -> 0 | K40: =IF(AND(Таблицаx_2[[#This Row],[Месяц окончания]]=Таблицаx_2[[#This Row],[Месяц]],Таблицаx_2[[#This Row],[id]]=A41,EDATE(Таблицаx_2[[#This Row],[Месяц]],2)=D41),F41,0) -> 0
A41: 575 | B41: изменение ЮЛ | C41: Васильев Артем Александрович | D41: 44896 | E41: стоп | F41: =IF(ISTEXT(Таблицаx_2[[#This Row],[Значение]]), 0, Таблицаx_2[[#This Row],[Значение]]) -> 0 | G41: 44896 | H41: =IFERROR(VLOOKUP(Таблицаx_2[[#This Row],[id]],prolongations!A:C,2,)," ") -> декабрь 2022 | I41: =IF(Таблицаx_2[[#This Row],[Месяц окончания]]=Таблицаx_2[[#This Row],[Месяц]],Таблицаx_2[[#This Row],[Значения числа]],0) -> 0 | J41: =IF(AND(Таблицаx_2[[#This Row],[Месяц окончания]]=Таблицаx_2[[#This Row],[Месяц]],Таблицаx_2[[#This Row],[id]]=A42,EDATE(Таблицаx_2[[#This Row],[Месяц]],1)=D42),F42,0) -> 0 | K41: =IF(AND(Таблицаx_2[[#This Row],[Месяц окончания]]=Таблицаx_2[[#This Row],[Месяц]],Таблицаx_2[[#This Row],[id]]=A42,EDATE(Таблицаx_2[[#This Row],[Месяц]],2)=D42),F42,0) -> 0
A42: 576 | B42: изменение ЮЛ | C42: Васильев Артем Александрович | D42: 44866 | E42: 36365 | F42: =IF(ISTEXT(Таблицаx_2[[#This Row],[Значение]]), 0, Таблицаx_2[[#This Row],[Значение]]) -> 36365 | G42: 44896 | H42: =IFERROR(VLOOKUP(Таблицаx_2[[#This Row],[id]],prolongations!A:C,2,)," ") -> декабрь 2022 | I42: =IF(Таблицаx_2[[#This Row],[Месяц окончания]]=Таблицаx_2[[#This Row],[Месяц]],Таблицаx_2[[#This Row],[Значения числа]],0) -> 0 | J42: =IF(AND(Таблицаx_2[[#This Row],[Месяц окончания]]=Таблицаx_2[[#This Row],[Месяц]],Таблицаx_2[[#This Row],[id]]=A43,EDATE(Таблицаx_2[[#This Row],[Месяц]],1)=D43),F43,0) -> 0 | K42: =IF(AND(Таблицаx_2[[#This Row],[Месяц окончания]]=Таблицаx_2[[#This Row],[Месяц]],Таблицаx_2[[#This Row],[id]]=A43,EDATE(Таблицаx_2[[#This Row],[Месяц]],2)=D43),F43,0) -> 0
A43: 576 | B43: изменение ЮЛ | C43: Васильев Артем Александрович | D43: 44896 | E43: стоп | F43: =IF(ISTEXT(Таблицаx_2[[#This Row],[Значение]]), 0, Таблицаx_2[[#This Row],[Значение]]) -> 0 | G43: 44896 | H43: =IFERROR(VLOOKUP(Таблицаx_2[[#This Row],[id]],prolongations!A:C,2,)," ") -> декабрь 2022 | I43: =IF(Таблицаx_2[[#This Row],[Месяц окончания]]=Таблицаx_2[[#This Row],[Месяц]],Таблицаx_2[[#This Row],[Значения числа]],0) -> 0 | J43: =IF(AND(Таблицаx_2[[#This Row],[Месяц окончания]]=Таблицаx_2[[#This Row],[Месяц]],Таблицаx_2[[#This Row],[id]]=A44,EDATE(Таблицаx_2[[#This Row],[Месяц]],1)=D44),F44,0) -> 0 | K43: =IF(AND(Таблицаx_2[[#This Row],[Месяц окончания]]=Таблицаx_2[[#This Row],[Месяц]],Таблицаx_2[[#This Row],[id]]=A44,EDATE(Таблицаx_2[[#This Row],[Месяц]],2)=D44),F44,0) -> 0
A44: 328 | C44: Иванова Мария Сергеевна | D44: 44866 | E44: 116473.5 | F44: =IF(ISTEXT(Таблицаx_2[[#This Row],[Значение]]), 0, Таблицаx_2[[#This Row],[Значение]]) -> 116473.5 | G44: 44896 | H44: =IFERROR(VLOOKUP(Таблицаx_2[[#This Row],[id]],prolongations!A:C,2,)," ") -> декабрь 2022 | I44: =IF(Таблицаx_2[[#This Row],[Месяц окончания]]=Таблицаx_2[[#This Row],[Месяц]],Таблицаx_2[[#This Row],[Значения числа]],0) -> 0 | J44: =IF(AND(Таблицаx_2[[#This Row],[Месяц окончания]]=Таблицаx_2[[#This Row],[Месяц]],Таблицаx_2[[#This Row],[id]]=A45,EDATE(Таблицаx_2[[#This Row],[Месяц]],1)=D45),F45,0) -> 0 | K44: =IF(AND(Таблицаx_2[[#This Row],[Месяц окончания]]=Таблицаx_2[[#This Row],[Месяц]],Таблицаx_2[[#This Row],[id]]=A45,EDATE(Таблицаx_2[[#This Row],[Месяц]],2)=D45),F45,0) -> 0
...

Sheet Весь отдел
A1: Месяц | B1: Пролонгация в первый месяц | E1: Пролонгация во второй месяц
B2: к пролонгации | C2: пролонгировано | D2: Коэффицент | E2: к пролонгации | F2: пролонгировано | G2: Коэффицент
A3: 44866
A4: 44896
A5: 44927 | B5: =IFERROR(SUMIF('financial data unpivot'!G:G,A4,'financial data unpivot'!I:I),0) -> 5986766.9 | C5: =IFERROR(SUMIF('financial data unpivot'!G:G,A4,'financial data unpivot'!J:J),0) -> 2585586.6 | D5: =IFERROR(C5/B5,0) -> 0.43188363 | E5: =IFERROR(SUMIF('financial data unpivot'!G:G,A3,'financial data unpivot'!I:I),0) -> 1898979 | F5: =IFERROR(SUMIF('financial data unpivot'!G:G,A3,'financial data unpivot'!K:K),0) -> 73380 | G5: =IFERROR(F5/E5,0) -> 0.038641818
A6: 44958 | B6: =IFERROR(SUMIF('financial data unpivot'!G:G,A5,'financial data unpivot'!I:I),0) -> 752795.5 | C6: =IFERROR(SUMIF('financial data unpivot'!G:G,A5,'financial data unpivot'!J:J),0) -> 137155 | D6: =IFERROR(C6/B6,0) -> 0.18219423 | E6: =IFERROR(SUMIF('financial data unpivot'!G:G,A4,'financial data unpivot'!I:I),0) -> 5986766.9 | F6: =IFERROR(SUMIF('financial data unpivot'!G:G,A4,'financial data unpivot'!K:K),0) -> 262620 | G6: =IFERROR(F6/E6,0) -> 0.043866749
A7: 44986 | B7: =IFERROR(SUMIF('financial data unpivot'!G:G,A6,'financial data unpivot'!I:I),0) -> 1114126 | C7: =IFERROR(SUMIF('financial data unpivot'!G:G,A6,'financial data unpivot'!J:J),0) -> 740747.65 | D7: =IFERROR(C7/B7,0) -> 0.66486882 | E7: =IFERROR(SUMIF('financial data unpivot'!G:G,A5,'financial data unpivot'!I:I),0) -> 752795.5 | F7: =IFERROR(SUMIF('financial data unpivot'!G:G,A5,'financial data unpivot'!K:K),0) -> 122999.08 | G7: =IFERROR(F7/E7,0) -> 0.16338977
A8: 45017 | B8: =IFERROR(SUMIF('financial data unpivot'!G:G,A7,'financial data unpivot'!I:I),0) -> 2147978 | C8: =IFERROR(SUMIF('financial data unpivot'!G:G,A7,'financial data unpivot'!J:J),0) -> 876170.35 | D8: =IFERROR(C8/B8,0) -> 0.40790471 | E8: =IFERROR(SUMIF('financial data unpivot'!G:G,A6,'financial data unpivot'!I:I),0) -> 1114126 | F8: =IFERROR(SUMIF('financial data unpivot'!G:G,A6,'financial data unpivot'!K:K),0) -> 17740 | G8: =IFERROR(F8/E8,0) -> 0.015922795
A9: 45047 | B9: =IFERROR(SUMIF('financial data unpivot'!G:G,A8,'financial data unpivot'!I:I),0) -> 1512668.5 | C9: =IFERROR(SUMIF('financial data unpivot'!G:G,A8,'financial data unpivot'!J:J),0) -> 619404.75 | D9: =IFERROR(C9/B9,0) -> 0.40947818 | E9: =IFERROR(SUMIF('financial data unpivot'!G:G,A7,'financial data unpivot'!I:I),0) -> 2147978 | F9: =IFERROR(SUMIF('financial data unpivot'!G:G,A7,'financial data unpivot'!K:K),0) -> 0 | G9: =IFERROR(F9/E9,0) -> 0
A10: 45078 | B10: =IFERROR(SUMIF('financial data unpivot'!G:G,A9,'financial data unpivot'!I:I),0) -> 1025588.5 | C10: =IFERROR(SUMIF('financial data unpivot'!G:G,A9,'financial data unpivot'!J:J),0) -> 104768 | D10: =IFERROR(C10/B10,0) -> 0.10215403 | E10: =IFERROR(SUMIF('financial data unpivot'!G:G,A8,'financial data unpivot'!I:I),0) -> 1512668.5 | F10: =IFERROR(SUMIF('financial data unpivot'!G:G,A8,'financial data unpivot'!K:K),0) -> 38632.5 | G10: =IFERROR(F10/E10,0) -> 0.025539304
A11: 45108 | B11: =IFERROR(SUMIF('financial data unpivot'!G:G,A10,'financial data unpivot'!I:I),0) -> 1153571.1 | C11: =IFERROR(SUMIF('financial data unpivot'!G:G,A10,'financial data unpivot'!J:J),0) -> 301260 | D11: =IFERROR(C11/B11,0) -> 0.26115425 | E11: =IFERROR(SUMIF('financial data unpivot'!G:G,A9,'financial data unpivot'!I:I),0) -> 1025588.5 | F11: =IFERROR(SUMIF('financial data unpivot'!G:G,A9,'financial data unpivot'!K:K),0) -> 94885 | G11: =IFERROR(F11/E11,0) -> 0.09251761
A12: 45139 | B12: =IFERROR(SUMIF('financial data unpivot'!G:G,A11,'financial data unpivot'!I:I),0) -> 1222393.3 | C12: =IFERROR(SUMIF('financial data unpivot'!G:G,A11,'financial data unpivot'!J:J),0) -> 424548.88 | D12: =IFERROR(C12/B12,0) -> 0.34730955 | E12: =IFERROR(SUMIF('financial data unpivot'!G:G,A10,'financial data unpivot'!I:I),0) -> 1153571.1 | F12: =IFERROR(SUMIF('financial data unpivot'!G:G,A10,'financial data unpivot'!K:K),0) -> 0 | G12: =IFERROR(F12/E12,0) -> 0
A13: 45170 | B13: =IFERROR(SUMIF('financial data unpivot'!G:G,A12,'financial data unpivot'!I:I),0) -> 2115914 | C13: =IFERROR(SUMIF('financial data unpivot'!G:G,A12,'financial data unpivot'!J:J),0) -> 927545.42 | D13: =IFERROR(C13/B13,0) -> 0.43836631 | E13: =IFERROR(SUMIF('financial data unpivot'!G:G,A11,'financial data unpivot'!I:I),0) -> 1222393.3 | F13: =IFERROR(SUMIF('financial data unpivot'!G:G,A11,'financial data unpivot'!K:K),0) -> 0 | G13: =IFERROR(F13/E13,0) -> 0
A14: 45200 | B14: =IFERROR(SUMIF('financial data unpivot'!G:G,A13,'financial data unpivot'!I:I),0) -> 1663092.6 | C14: =IFERROR(SUMIF('financial data unpivot'!G:G,A13,'financial data unpivot'!J:J),0) -> 1433344.6 | D14: =IFERROR(C14/B14,0) -> 0.86185494 | E14: =IFERROR(SUMIF('financial data unpivot'!G:G,A12,'financial data unpivot'!I:I),0) -> 2115914 | F14: =IFERROR(SUMIF('financial data unpivot'!G:G,A12,'financial data unpivot'!K:K),0) -> 82020 | G14: =IFERROR(F14/E14,0) -> 0.03876339
A15: 45231 | B15: =IFERROR(SUMIF('financial data unpivot'!G:G,A14,'financial data unpivot'!I:I),0) -> 1075210 | C15: =IFERROR(SUMIF('financial data unpivot'!G:G,A14,'financial data unpivot'!J:J),0) -> 719019 | D15: =IFERROR(C15/B15,0) -> 0.66872427 | E15: =IFERROR(SUMIF('financial data unpivot'!G:G,A13,'financial data unpivot'!I:I),0) -> 1663092.6 | F15: =IFERROR(SUMIF('financial data unpivot'!G:G,A13,'financial data unpivot'!K:K),0) -> 0 | G15: =IFERROR(F15/E15,0) -> 0
A16: 45261 | B16: =IFERROR(SUMIF('financial data unpivot'!G:G,A15,'financial data unpivot'!I:I),0) -> 1119808.1 | C16: =IFERROR(SUMIF('financial data unpivot'!G:G,A15,'financial data unpivot'!J:J),0) -> 227292.52 | D16: =IFERROR(C16/B16,0) -> 0.20297453 | E16: =IFERROR(SUMIF('financial data unpivot'!G:G,A14,'financial data unpivot'!I:I),0) -> 1075210 | F16: =IFERROR(SUMIF('financial data unpivot'!G:G,A14,'financial data unpivot'!K:K),0) -> 155640 | G16: =IFERROR(F16/E16,0) -> 0.14475312

Sheet Менеджер за год
A1: Менеджер | B1: Пролонгация в первый месяц | E1: Пролонгация во второй месяц
B2: к пролонгации | C2: пролонгировано | D2: Коэффицент | E2: к пролонгации | F2: пролонгировано | G2: Коэффицент
A3: Васильев Артем Александрович | B3: =IFERROR(SUMIF('financial data unpivot'!C:C,'Менеджер за год'!A3,'financial data unpivot'!I:I),0) -> 8380223.4 | C3: =IFERROR(SUMIF('financial data unpivot'!C:C,'Менеджер за год'!A3,'financial data unpivot'!J:J),0) -> 3781646.5 | D3: =IFERROR(C3/B3,0) -> 0.45125844 | E3: =IFERROR(SUMIF('financial data unpivot'!C:C,'Менеджер за год'!A3,'financial data unpivot'!I:I),0) -> 8380223.4 | F3: =IFERROR(SUMIF('financial data unpivot'!C:C,'Менеджер за год'!A3,'financial data unpivot'!K:K),0) -> 335835 | G3: =IFERROR(F3/E3,0) -> 0.040074707
A4: Михайлов Андрей Сергеевич | B4: =IFERROR(SUMIF('financial data unpivot'!C:C,'Менеджер за год'!A4,'financial data unpivot'!I:I),0) -> 1645180.2 | C4: =IFERROR(SUMIF('financial data unpivot'!C:C,'Менеджер за год'!A4,'financial data unpivot'!J:J),0) -> 1215589.8 | D4: =IFERROR(C4/B4,0) -> 0.7388794 | E4: =IFERROR(SUMIF('financial data unpivot'!C:C,'Менеджер за год'!A4,'financial data unpivot'!I:I),0) -> 1645180.2 | F4: =IFERROR(SUMIF('financial data unpivot'!C:C,'Менеджер за год'!A4,'financial data unpivot'!K:K),0) -> 0 | G4: =IFERROR(F4/E4,0) -> 0
A5: Соколова Анастасия Викторовна | B5: =IFERROR(SUMIF('financial data unpivot'!C:C,'Менеджер за год'!A5,'financial data unpivot'!I:I),0) -> 4523555 | C5: =IFERROR(SUMIF('financial data unpivot'!C:C,'Менеджер за год'!A5,'financial data unpivot'!J:J),0) -> 1908950.4 | D5: =IFERROR(C5/B5,0) -> 0.42200226 | E5: =IFERROR(SUMIF('financial data unpivot'!C:C,'Менеджер за год'!A5,'financial data unpivot'!I:I),0) -> 4523555 | F5: =IFERROR(SUMIF('financial data unpivot'!C:C,'Менеджер за год'!A5,'financial data unpivot'!K:K),0) -> 46995 | G5: =IFERROR(F5/E5,0) -> 0.010388953
A6: Иванова Мария Сергеевна | B6: =IFERROR(SUMIF('financial data unpivot'!C:C,'Менеджер за год'!A6,'financial data unpivot'!I:I),0) -> 3427787.9 | C6: =IFERROR(SUMIF('financial data unpivot'!C:C,'Менеджер за год'!A6,'financial data unpivot'!J:J),0) -> 579854.3 | D6: =IFERROR(C6/B6,0) -> 0.16916283 | E6: =IFERROR(SUMIF('financial data unpivot'!C:C,'Менеджер за год'!A6,'financial data unpivot'!I:I),0) -> 3427787.9 | F6: =IFERROR(SUMIF('financial data unpivot'!C:C,'Менеджер за год'!A6,'financial data unpivot'!K:K),0) -> 112012.5 | G6: =IFERROR(F6/E6,0) -> 0.03267778
A7: Попова Екатерина Николаевна | B7: =IFERROR(SUMIF('financial data unpivot'!C:C,'Менеджер за год'!A7,'financial data unpivot'!I:I),0) -> 3973343.7 | C7: =IFERROR(SUMIF('financial data unpivot'!C:C,'Менеджер за год'!A7,'financial data unpivot'!J:J),0) -> 1830067.3 | D7: =IFERROR(C7/B7,0) -> 0.46058621 | E7: =IFERROR(SUMIF('financial data unpivot'!C:C,'Менеджер за год'!A7,'financial data unpivot'!I:I),0) -> 3973343.7 | F7: =IFERROR(SUMIF('financial data unpivot'!C:C,'Менеджер за год'!A7,'financial data unpivot'!K:K),0) -> 85400 | G7: =IFERROR(F7/E7,0) -> 0.021493233
A8: Смирнова Ольга Владимировна | B8: =IFERROR(SUMIF('financial data unpivot'!C:C,'Менеджер за год'!A8,'financial data unpivot'!I:I),0) -> 3454191.6 | C8: =IFERROR(SUMIF('financial data unpivot'!C:C,'Менеджер за год'!A8,'financial data unpivot'!J:J),0) -> 2139438.2 | D8: =IFERROR(C8/B8,0) -> 0.61937449 | E8: =IFERROR(SUMIF('financial data unpivot'!C:C,'Менеджер за год'!A8,'financial data unpivot'!I:I),0) -> 3454191.6 | F8: =IFERROR(SUMIF('financial data unpivot'!C:C,'Менеджер за год'!A8,'financial data unpivot'!K:K),0) -> 329160 | G8: =IFERROR(F8/E8,0) -> 0.095292918
A9: Кузнецов Михаил Иванович | B9: =IFERROR(SUMIF('financial data unpivot'!C:C,'Менеджер за год'!A9,'financial data unpivot'!I:I),0) -> 1307609.5 | C9: =IFERROR(SUMIF('financial data unpivot'!C:C,'Менеджер за год'!A9,'financial data unpivot'!J:J),0) -> 541800.55 | D9: =IFERROR(C9/B9,0) -> 0.41434432 | E9: =IFERROR(SUMIF('financial data unpivot'!C:C,'Менеджер за год'!A9,'financial data unpivot'!I:I),0) -> 1307609.5 | F9: =IFERROR(SUMIF('financial data unpivot'!C:C,'Менеджер за год'!A9,'financial data unpivot'!K:K),0) -> 117124.08 | G9: =IFERROR(F9/E9,0) -> 0.089571148
A10: Петрова Анна Дмитриевна | B10: =IFERROR(SUMIF('financial data unpivot'!C:C,'Менеджер за год'!A10,'financial data unpivot'!I:I),0) -> 98492 | C10: =IFERROR(SUMIF('financial data unpivot'!C:C,'Менеджер за год'!A10,'financial data unpivot'!J:J),0) -> 109442.52 | D10: =IFERROR(C10/B10,0) -> 1.1111818 | E10: =IFERROR(SUMIF('financial data unpivot'!C:C,'Менеджер за год'!A10,'financial data unpivot'!I:I),0) -> 98492 | F10: =IFERROR(SUMIF('financial data unpivot'!C:C,'Менеджер за год'!A10,'financial data unpivot'!K:K),0) -> 0 | G10: =IFERROR(F10/E10,0) -> 0
A11: Федорова Марина Васильевна | B11: =IFERROR(SUMIF('financial data unpivot'!C:C,'Менеджер за год'!A11,'financial data unpivot'!I:I),0) -> 128250 | C11: =IFERROR(SUMIF('financial data unpivot'!C:C,'Менеджер за год'!A11,'financial data unpivot'!J:J),0) -> 73050 | D11: =IFERROR(C11/B11,0) -> 0.56959064 | E11: =IFERROR(SUMIF('financial data unpivot'!C:C,'Менеджер за год'!A11,'financial data unpivot'!I:I),0) -> 128250 | F11: =IFERROR(SUMIF('financial data unpivot'!C:C,'Менеджер за год'!A11,'financial data unpivot'!K:K),0) -> 0 | G11: =IFERROR(F11/E11,0) -> 0
A12: без А/М | B12: =IFERROR(SUMIF('financial data unpivot'!C:C,'Менеджер за год'!A12,'financial data unpivot'!I:I),0) -> 0 | C12: =IFERROR(SUMIF('financial data unpivot'!C:C,'Менеджер за год'!A12,'financial data unpivot'!J:J),0) -> 0 | D12: =IFERROR(C12/B12,0) -> 0 | E12: =IFERROR(SUMIF('financial data unpivot'!C:C,'Менеджер за год'!A12,'financial data unpivot'!I:I),0) -> 0 | F12: =IFERROR(SUMIF('financial data unpivot'!C:C,'Менеджер за год'!A12,'financial data unpivot'!K:K),0) -> 0 | G12: =IFERROR(F12/E12,0) -> 0

Sheet Менеджеры по месяцам
A1: Коэффицент 1
A2: Менеджер | B2: Месяц
B3: 44866 | C3: 44896 | D3: 44927 | E3: 44958 | F3: 44986 | G3: 45017 | H3: 45047 | I3: 45078 | J3: 45108 | K3: 45139 | L3: 45170 | M3: 45200 | N3: 45231 | O3: 45261
A4: Васильев Артем Александрович | D4: =IFERROR(SUMIFS('financial data unpivot'!$J:$J,'financial data unpivot'!$C:$C,'Менеджеры по месяцам'!$A4,'financial data unpivot'!$G:$G,'Менеджеры по месяцам'!C$3)/SUMIFS('financial data unpivot'!$I:$I,'financial data unpivot'!$C:$C,'Менеджеры по месяцам'!$A4,'financial data unpivot'!$G:$G,'Менеджеры по месяцам'!C$3),0) -> 0.59070739 | E4: =IFERROR(SUMIFS('financial data unpivot'!$J:$J,'financial data unpivot'!$C:$C,'Менеджеры по месяцам'!$A4,'financial data unpivot'!$G:$G,'Менеджеры по месяцам'!D$3)/SUMIFS('financial data unpivot'!$I:$I,'financial data unpivot'!$C:$C,'Менеджеры по месяцам'!$A4,'financial data unpivot'!$G:$G,'Менеджеры по месяцам'!D$3),0) -> 0 | F4: =IFERROR(SUMIFS('financial data unpivot'!$J:$J,'financial data unpivot'!$C:$C,'Менеджеры по месяцам'!$A4,'financial data unpivot'!$G:$G,'Менеджеры по месяцам'!E$3)/SUMIFS('financial data unpivot'!$I:$I,'financial data unpivot'!$C:$C,'Менеджеры по месяцам'!$A4,'financial data unpivot'!$G:$G,'Менеджеры по месяцам'!E$3),0) -> 0.54461463 | G4: =IFERROR(SUMIFS('financial data unpivot'!$J:$J,'financial data unpivot'!$C:$C,'Менеджеры по месяцам'!$A4,'financial data unpivot'!$G:$G,'Менеджеры по месяцам'!F$3)/SUMIFS('financial data unpivot'!$I:$I,'financial data unpivot'!$C:$C,'Менеджеры по месяцам'!$A4,'financial data unpivot'!$G:$G,'Менеджеры по месяцам'!F$3),0) -> 0.49563586 | H4: =IFERROR(SUMIFS('financial data unpivot'!$J:$J,'financial data unpivot'!$C:$C,'Менеджеры по месяцам'!$A4,'financial data unpivot'!$G:$G,'Менеджеры по месяцам'!G$3)/SUMIFS('financial data unpivot'!$I:$I,'financial data unpivot'!$C:$C,'Менеджеры по месяцам'!$A4,'financial data unpivot'!$G:$G,'Менеджеры по месяцам'!G$3),0) -> 0 | I4: =IFERROR(SUMIFS('financial data unpivot'!$J:$J,'financial data unpivot'!$C:$C,'Менеджеры по месяцам'!$A4,'financial data unpivot'!$G:$G,'Менеджеры по месяцам'!H$3)/SUMIFS('financial data unpivot'!$I:$I,'financial data unpivot'!$C:$C,'Менеджеры по месяцам'!$A4,'financial data unpivot'!$G:$G,'Менеджеры по месяцам'!H$3),0) -> 0 | J4: =IFERROR(SUMIFS('financial data unpivot'!$J:$J,'financial data unpivot'!$C:$C,'Менеджеры по месяцам'!$A4,'financial data unpivot'!$G:$G,'Менеджеры по месяцам'!I$3)/SUMIFS('financial data unpivot'!$I:$I,'financial data unpivot'!$C:$C,'Менеджеры по месяцам'!$A4,'financial data unpivot'!$G:$G,'Менеджеры по месяцам'!I$3),0) -> 0.96969919 | K4: =IFERROR(SUMIFS('financial data unpivot'!$J:$J,'financial data unpivot'!$C:$C,'Менеджеры по месяцам'!$A4,'financial data unpivot'!$G:$G,'Менеджеры по месяцам'!J$3)/SUMIFS('financial data unpivot'!$I:$I,'financial data unpivot'!$C:$C,'Менеджеры по месяцам'!$A4,'financial data unpivot'!$G:$G,'Менеджеры по месяцам'!J$3),0) -> 0.2970297 | ... O4: =IFERROR(SUMIFS('financial data unpivot'!$J:$J,'financial data unpivot'!$C:$C,'Менеджеры по месяцам'!$A4,'financial data unpivot'!$G:$G,'Менеджеры по месяцам'!N$3)/SUMIFS('financial data unpivot'!$I:$I,'financial data unpivot'!$C:$C,'Менеджеры по месяцам'!$A4,'financial data unpivot'!$G:$G,'Менеджеры по месяцам'!N$3),0) -> 0
A5: Михайлов Андрей Сергеевич | D5: =IFERROR(SUMIFS('financial data unpivot'!$J:$J,'financial data unpivot'!$C:$C,'Менеджеры по месяцам'!$A5,'financial data unpivot'!$G:$G,'Менеджеры по месяцам'!C$3)/SUMIFS('financial data unpivot'!$I:$I,'financial data unpivot'!$C:$C,'Менеджеры по месяцам'!$A5,'financial data unpivot'!$G:$G,'Менеджеры по месяцам'!C$3),0) -> 0.36636478 | E5: =IFERROR(SUMIFS('financial data unpivot'!$J:$J,'financial data unpivot'!$C:$C,'Менеджеры по месяцам'!$A5,'financial data unpivot'!$G:$G,'Менеджеры по месяцам'!D$3)/SUMIFS('financial data unpivot'!$I:$I,'financial data unpivot'!$C:$C,'Менеджеры по месяцам'!$A5,'financial data unpivot'!$G:$G,'Менеджеры по месяцам'!D$3),0) -> 0 | F5: =IFERROR(SUMIFS('financial data unpivot'!$J:$J,'financial data unpivot'!$C:$C,'Менеджеры по месяцам'!$A5,'financial data unpivot'!$G:$G,'Менеджеры по месяцам'!E$3)/SUMIFS('financial data unpivot'!$I:$I,'financial data unpivot'!$C:$C,'Менеджеры по месяцам'!$A5,'financial data unpivot'!$G:$G,'Менеджеры по месяцам'!E$3),0) -> 0 | G5: =IFERROR(SUMIFS('financial data unpivot'!$J:$J,'financial data unpivot'!$C:$C,'Менеджеры по месяцам'!$A5,'financial data unpivot'!$G:$G,'Менеджеры по месяцам'!F$3)/SUMIFS('financial data unpivot'!$I:$I,'financial data unpivot'!$C:$C,'Менеджеры по месяцам'!$A5,'financial data unpivot'!$G:$G,'Менеджеры по месяцам'!F$3),0) -> 0 | H5: =IFERROR(SUMIFS('financial data unpivot'!$J:$J,'financial data unpivot'!$C:$C,'Менеджеры по месяцам'!$A5,'financial data unpivot'!$G:$G,'Менеджеры по месяцам'!G$3)/SUMIFS('financial data unpivot'!$I:$I,'financial data unpivot'!$C:$C,'Менеджеры по месяцам'!$A5,'financial data unpivot'!$G:$G,'Менеджеры по месяцам'!G$3),0) -> 1.3308369 | I5: =IFERROR(SUMIFS('financial data unpivot'!$J:$J,'financial data unpivot'!$C:$C,'Менеджеры по месяцам'!$A5,'financial data unpivot'!$G:$G,'Менеджеры по месяцам'!H$3)/SUMIFS('financial data unpivot'!$I:$I,'financial data unpivot'!$C:$C,'Менеджеры по месяцам'!$A5,'financial data unpivot'!$G:$G,'Менеджеры по месяцам'!H$3),0) -> 0 | J5: =IFERROR(SUMIFS('financial data unpivot'!$J:$J,'financial data unpivot'!$C:$C,'Менеджеры по месяцам'!$A5,'financial data unpivot'!$G:$G,'Менеджеры по месяцам'!I$3)/SUMIFS('financial data unpivot'!$I:$I,'financial data unpivot'!$C:$C,'Менеджеры по месяцам'!$A5,'financial data unpivot'!$G:$G,'Менеджеры по месяцам'!I$3),0) -> 1.1975246 | K5: =IFERROR(SUMIFS('financial data unpivot'!$J:$J,'financial data unpivot'!$C:$C,'Менеджеры по месяцам'!$A5,'financial data unpivot'!$G:$G,'Менеджеры по месяцам'!J$3)/SUMIFS('financial data unpivot'!$I:$I,'financial data unpivot'!$C:$C,'Менеджеры по месяцам'!$A5,'financial data unpivot'!$G:$G,'Менеджеры по месяцам'!J$3),0) -> 0 | ... O5: =IFERROR(SUMIFS('financial data unpivot'!$J:$J,'financial data unpivot'!$C:$C,'Менеджеры по месяцам'!$A5,'financial data unpivot'!$G:$G,'Менеджеры по месяцам'!N$3)/SUMIFS('financial data unpivot'!$I:$I,'financial data unpivot'!$C:$C,'Менеджеры по месяцам'!$A5,'financial data unpivot'!$G:$G,'Менеджеры по месяцам'!N$3),0) -> 0
A6: Соколова Анастасия Викторовна | D6: =IFERROR(SUMIFS('financial data unpivot'!$J:$J,'financial data unpivot'!$C:$C,'Менеджеры по месяцам'!$A6,'financial data unpivot'!$G:$G,'Менеджеры по месяцам'!C$3)/SUMIFS('financial data unpivot'!$I:$I,'financial data unpivot'!$C:$C,'Менеджеры по месяцам'!$A6,'financial data unpivot'!$G:$G,'Менеджеры по месяцам'!C$3),0) -> 0.51441028 | E6: =IFERROR(SUMIFS('financial data unpivot'!$J:$J,'financial data unpivot'!$C:$C,'Менеджеры по месяцам'!$A6,'financial data unpivot'!$G:$G,'Менеджеры по месяцам'!D$3)/SUMIFS('financial data unpivot'!$I:$I,'financial data unpivot'!$C:$C,'Менеджеры по месяцам'!$A6,'financial data unpivot'!$G:$G,'Менеджеры по месяцам'!D$3),0) -> 0.35432008 | F6: =IFERROR(SUMIFS('financial data unpivot'!$J:$J,'financial data unpivot'!$C:$C,'Менеджеры по месяцам'!$A6,'financial data unpivot'!$G:$G,'Менеджеры по месяцам'!E$3)/SUMIFS('financial data unpivot'!$I:$I,'financial data unpivot'!$C:$C,'Менеджеры по месяцам'!$A6,'financial data unpivot'!$G:$G,'Менеджеры по месяцам'!E$3),0) -> 1.1961797 | G6: =IFERROR(SUMIFS('financial data unpivot'!$J:$J,'financial data unpivot'!$C:$C,'Менеджеры по месяцам'!$A6,'financial data unpivot'!$G:$G,'Менеджеры по месяцам'!F$3)/SUMIFS('financial data unpivot'!$I:$I,'financial data unpivot'!$C:$C,'Менеджеры по месяцам'!$A6,'financial data unpivot'!$G:$G,'Менеджеры по месяцам'!F$3),0) -> 0.86062179 | H6: =IFERROR(SUMIFS('financial data unpivot'!$J:$J,'financial data unpivot'!$C:$C,'Менеджеры по месяцам'!$A6,'financial data unpivot'!$G:$G,'Менеджеры по месяцам'!G$3)/SUMIFS('financial data unpivot'!$I:$I,'financial data unpivot'!$C:$C,'Менеджеры по месяцам'!$A6,'financial data unpivot'!$G:$G,'Менеджеры по месяцам'!G$3),0) -> 0.096547643 | I6: =IFERROR(SUMIFS('financial data unpivot'!$J:$J,'financial data unpivot'!$C:$C,'Менеджеры по месяцам'!$A6,'financial data unpivot'!$G:$G,'Менеджеры по месяцам'!H$3)/SUMIFS('financial data unpivot'!$I:$I,'financial data unpivot'!$C:$C,'Менеджеры по месяцам'!$A6,'financial data unpivot'!$G:$G,'Менеджеры по месяцам'!H$3),0) -> 0 | J6: =IFERROR(SUMIFS('financial data unpivot'!$J:$J,'financial data unpivot'!$C:$C,'Менеджеры по месяцам'!$A6,'financial data unpivot'!$G:$G,'Менеджеры по месяцам'!I$3)/SUMIFS('financial data unpivot'!$I:$I,'financial data unpivot'!$C:$C,'Менеджеры по месяцам'!$A6,'financial data unpivot'!$G:$G,'Менеджеры по месяцам'!I$3),0) -> 0.10565039 | K6: =IFERROR(SUMIFS('financial data unpivot'!$J:$J,'financial data unpivot'!$C:$C,'Менеджеры по месяцам'!$A6,'financial data unpivot'!$G:$G,'Менеджеры по месяцам'!J$3)/SUMIFS('financial data unpivot'!$I:$I,'financial data unpivot'!$C:$C,'Менеджеры по месяцам'!$A6,'financial data unpivot'!$G:$G,'Менеджеры по месяцам'!J$3),0) -> 0 | ... O6: =IFERROR(SUMIFS('financial data unpivot'!$J:$J,'financial data unpivot'!$C:$C,'Менеджеры по месяцам'!$A6,'financial data unpivot'!$G:$G,'Менеджеры по месяцам'!N$3)/SUMIFS('financial data unpivot'!$I:$I,'financial data unpivot'!$C:$C,'Менеджеры по месяцам'!$A6,'financial data unpivot'!$G:$G,'Менеджеры по месяцам'!N$3),0) -> 0.14701558
A7: Иванова Мария Сергеевна | D7: =IFERROR(SUMIFS('financial data unpivot'!$J:$J,'financial data unpivot'!$C:$C,'Менеджеры по месяцам'!$A7,'financial data unpivot'!$G:$G,'Менеджеры по месяцам'!C$3)/SUMIFS('financial data unpivot'!$I:$I,'financial data unpivot'!$C:$C,'Менеджеры по месяцам'!$A7,'financial data unpivot'!$G:$G,'Менеджеры по месяцам'!C$3),0) -> 0.17610819 | E7: =IFERROR(SUMIFS('financial data unpivot'!$J:$J,'financial data unpivot'!$C:$C,'Менеджеры по месяцам'!$A7,'financial data unpivot'!$G:$G,'Менеджеры по месяцам'!D$3)/SUMIFS('financial data unpivot'!$I:$I,'financial data unpivot'!$C:$C,'Менеджеры по месяцам'!$A7,'financial data unpivot'!$G:$G,'Менеджеры по месяцам'!D$3),0) -> 0 | F7: =IFERROR(SUMIFS('financial data unpivot'!$J:$J,'financial data unpivot'!$C:$C,'Менеджеры по месяцам'!$A7,'financial data unpivot'!$G:$G,'Менеджеры по месяцам'!E$3)/SUMIFS('financial data unpivot'!$I:$I,'financial data unpivot'!$C:$C,'Менеджеры по месяцам'!$A7,'financial data unpivot'!$G:$G,'Менеджеры по месяцам'!E$3),0) -> 0 | G7: =IFERROR(SUMIFS('financial data unpivot'!$J:$J,'financial data unpivot'!$C:$C,'Менеджеры по месяцам'!$A7,'financial data unpivot'!$G:$G,'Менеджеры по месяцам'!F$3)/SUMIFS('financial data unpivot'!$I:$I,'financial data unpivot'!$C:$C,'Менеджеры по месяцам'!$A7,'financial data unpivot'!$G:$G,'Менеджеры по месяцам'!F$3),0) -> 0.12081651 | H7: =IFERROR(SUMIFS('financial data unpivot'!$J:$J,'financial data unpivot'!$C:$C,'Менеджеры по месяцам'!$A7,'financial data unpivot'!$G:$G,'Менеджеры по месяцам'!G$3)/SUMIFS('financial data unpivot'!$I:$I,'financial data unpivot'!$C:$C,'Менеджеры по месяцам'!$A7,'financial data unpivot'!$G:$G,'Менеджеры по месяцам'!G$3),0) -> 0 | I7: =IFERROR(SUMIFS('financial data unpivot'!$J:$J,'financial data unpivot'!$C:$C,'Менеджеры по месяцам'!$A7,'financial data unpivot'!$G:$G,'Менеджеры по месяцам'!H$3)/SUMIFS('financial data unpivot'!$I:$I,'financial data unpivot'!$C:$C,'Менеджеры по месяцам'!$A7,'financial data unpivot'!$G:$G,'Менеджеры по месяцам'!H$3),0) -> 0 | J7: =IFERROR(SUMIFS('financial data unpivot'!$J:$J,'financial data unpivot'!$C:$C,'Менеджеры по месяцам'!$A7,'financial data unpivot'!$G:$G,'Менеджеры по месяцам'!I$3)/SUMIFS('financial data unpivot'!$I:$I,'financial data unpivot'!$C:$C,'Менеджеры по месяцам'!$A7,'financial data unpivot'!$G:$G,'Менеджеры по месяцам'!I$3),0) -> 0 | K7: =IFERROR(SUMIFS('financial data unpivot'!$J:$J,'financial data unpivot'!$C:$C,'Менеджеры по месяцам'!$A7,'financial data unpivot'!$G:$G,'Менеджеры по месяцам'!J$3)/SUMIFS('financial data unpivot'!$I:$I,'financial data unpivot'!$C:$C,'Менеджеры по месяцам'!$A7,'financial data unpivot'!$G:$G,'Менеджеры по месяцам'!J$3),0) -> 0.45119943 | ... O7: =IFERROR(SUMIFS('financial data unpivot'!$J:$J,'financial data unpivot'!$C:$C,'Менеджеры по месяцам'!$A7,'financial data unpivot'!$G:$G,'Менеджеры по месяцам'!N$3)/SUMIFS('financial data unpivot'!$I:$I,'financial data unpivot'!$C:$C,'Менеджеры по месяцам'!$A7,'financial data unpivot'!$G:$G,'Менеджеры по месяцам'!N$3),0) -> 0
