Workbook

Sheet Задания
A2: Данные: | B2: Файл содержит несколько вкладок с иcходными данными
A4: ОТЧЕТ | B4: на данной вкладке расположена информация по сканированию товаров.
B5: Унифицированное название SKU | C5: наименование товара
B6: Кол-во | C6: кол-во проданных упаковок
B7: Стоимость товара | C7: стоимовть товара
B8: Адрес | C8: адрес аптеки
B9: ИНН | C9: ИНН аптеки
B10: Название аптеки | C10: название аптеки
B11: Дата продажи | C11: когда продан товар
B12: Время продажи
B13: Дата сканирования | C13: когда отсканирован товар
B14: Время сканирования
B15: Пользователь
B16: Номер Чека
A18: Справочник сети
B19: на вкладке содержится информация принадлежности ИНН к той или иной аптечной сети (АС)
B20: Обращаем внимание, что все ИНН из вкладки "ОТЧЕТ" содержатся в справочнике
A21: Справочник по %
B22: на вкладке содержится информация по %, за который клиент платит дополнительно
A26: Задания: | B26: Просьба в исходниках выделить цветом все дополнительно добавляемые поля.
A28: 1 | B28: Для каждого SKU необходимо посмотреть сколько упаковок продано, на какую сумму и в скольких аптеках в той или иной сети
A29: 2 | B29: Посчитать сколько клиент должен заплатить дополнительно, если:
A30: 2.1 | B30: Размер и тип комиссии прописан в справочнике. (размеры и формула расчета указаны на вкладке "Справочник по %")
A31: 2.2 | B31: Размер комиссии для SKU3=20%, для остальных 15%
A32: 3 | B32: Показать сколько пользователей загружают чеки в систему в зависимости от частоты сканирования

Sheet ОТЧЕТ
A1: Унифицированное название SKU | B1: Кол-во | C1: Стоимость товаров | D1: Оплата | E1: Оплата (2) | F1: Адрес | G1: ИНН | H1: Название аптеки | I1: Название сети | J1: Дата продажи | K1: Время продажи | L1: Дата сканирования | M1: Дата сканирования | N1: Время скан-я | O1: Пользователь | P1: Номер Чека | Q1: SKU unique | R1: Польз. unique | S1: Заказ / польз. | V1: Кол-во | W1: Сумма | X1: Уник. Сеть | Z1: мин / макс дата | AA1: мес. Между | AC1: чеков за 2.5 мес | AD1: кол-во
A2: SKU2 | B2: 1 | C2: 645 | D2: =C2+IF(INDEX('Справочник по %'!B:B,(MATCH(A2,'Справочник по %'!A:A,0)))="кол-во",B2*INDEX('Справочник по %'!C:C,(MATCH(A2,'Справочник по %'!A:A,0))),ОТЧЕТ!C2*INDEX('Справочник по %'!C:C,(MATCH(A2,'Справочник по %'!A:A,0))))/100 -> 645.2 | E2: =IF(ОТЧЕТ!A2="SKU3",C2+ОТЧЕТ!C2*0.2,C2+ОТЧЕТ!C2*0.15) -> 741.75 | F2: Ярославская обл, г Рыбинск, ул Плеханова, д 37А | G2: 5904196645 | H2: Аптека;сайт:www.planetazdorovo.ru | I2: =INDEX('Справочник Сети'!B:B,(MATCH(G2,'Справочник Сети'!C:C,0))) -> 36,6 | J2: 2025-02-24 | K2: 11:39:00 | L2: 2025-02-24 | M2: 45712 | N2: 11:41:38 | O2: 3612 | P2: 6 | Q2: =IF(COUNTIFS(A$2:A2,A2,I$2:I2,I2)=1,1,0) -> 1 | R2: =COUNTIF(O:O,O2) -> 2 | S2: =IF(COUNTIF(O$2:O2,O2)=1,R2,0)/2.5 -> 0.8 | U2: SKU1 | V2: =SUMIF(A:A,U2,B:B) -> 2201 | W2: =SUMPRODUCT(--(A:A=U2),B:B,C:C) -> 959741.43 | X2: =SUMIF(A:A,U2,Q:Q) -> 7 | Z2: =MIN(M:M) -> 45658 | AA2: =(Z3-Z2)/30 -> 2.4666667 | AC2: <= 1 | AD2: =COUNTIF(S:S,"<=1") -> 2505
A3: SKU1 | B3: 1 | C3: 538 | D3: =C3+IF(INDEX('Справочник по %'!B:B,(MATCH(A3,'Справочник по %'!A:A,0)))="кол-во",B3*INDEX('Справочник по %'!C:C,(MATCH(A3,'Справочник по %'!A:A,0))),ОТЧЕТ!C3*INDEX('Справочник по %'!C:C,(MATCH(A3,'Справочник по %'!A:A,0))))/100 -> 591.8 | E3: =IF(ОТЧЕТ!A3="SKU3",C3+ОТЧЕТ!C3*0.2,C3+ОТЧЕТ!C3*0.15) -> 618.7 | F3: Ярославская обл, г Рыбинск, ул Моторостроителей, д 16А | G3: 2539096225 | H3: ул. Черемуховая, 22, Касса №3 | I3: =INDEX('Справочник Сети'!B:B,(MATCH(G3,'Справочник Сети'!C:C,0))) -> 36,6 | J3: 2025-03-10 | K3: 12:43:00 | L3: 2025-03-10 | M3: 45726 | N3: 11:43:03 | O3: 1096 | P3: 8 | Q3: =IF(COUNTIFS(A$2:A3,A3,I$2:I3,I3)=1,1,0) -> 1 | R3: =COUNTIF(O:O,O3) -> 1 | S3: =IF(COUNTIF(O$2:O3,O3)=1,R3,0)/2.5 -> 0.4 | U3: SKU2 | V3: =SUMIF(A:A,U3,B:B) -> 565 | W3: =SUMPRODUCT(--(A:A=U3),B:B,C:C) -> 347144.14 | X3: =SUMIF(A:A,U3,Q:Q) -> 7 | Z3: =MAX(M:M) -> 45732 | AC3: > 1 | AD3: =COUNTIFS(S:S,">1",S:S,"<=3") -> 273
A4: SKU1 | B4: 1 | C4: 563 | D4: =C4+IF(INDEX('Справочник по %'!B:B,(MATCH(A4,'Справочник по %'!A:A,0)))="кол-во",B4*INDEX('Справочник по %'!C:C,(MATCH(A4,'Справочник по %'!A:A,0))),ОТЧЕТ!C4*INDEX('Справочник по %'!C:C,(MATCH(A4,'Справочник по %'!A:A,0))))/100 -> 619.3 | E4: =IF(ОТЧЕТ!A4="SKU3",C4+ОТЧЕТ!C4*0.2,C4+ОТЧЕТ!C4*0.15) -> 647.45 | F4: Ярославская обл, г Рыбинск, ул Крестовая/Гоголя, д 29/15 | G4: 2722039794 | H4: Аптека | I4: =INDEX('Справочник Сети'!B:B,(MATCH(G4,'Справочник Сети'!C:C,0))) -> 36,6 | J4: 2025-03-09 | K4: 16:38:00 | L4: 2025-03-10 | M4: 45726 | N4: 11:53:04 | O4: 1322 | P4: 10 | Q4: =IF(COUNTIFS(A$2:A4,A4,I$2:I4,I4)=1,1,0) -> 0 | R4: =COUNTIF(O:O,O4) -> 1 | S4: =IF(COUNTIF(O$2:O4,O4)=1,R4,0)/2.5 -> 0.4 | U4: SKU3 | V4: =SUMIF(A:A,U4,B:B) -> 29 | W4: =SUMPRODUCT(--(A:A=U4),B:B,C:C) -> 21815.6 | X4: =SUMIF(A:A,U4,Q:Q) -> 4 | AC4: > 3 | AD4: =COUNTIF(S:S,">3") -> 20
A5: SKU2 | B5: 1 | C5: 645 | D5: =C5+IF(INDEX('Справочник по %'!B:B,(MATCH(A5,'Справочник по %'!A:A,0)))="кол-во",B5*INDEX('Справочник по %'!C:C,(MATCH(A5,'Справочник по %'!A:A,0))),ОТЧЕТ!C5*INDEX('Справочник по %'!C:C,(MATCH(A5,'Справочник по %'!A:A,0))))/100 -> 645.2 | E5: =IF(ОТЧЕТ!A5="SKU3",C5+ОТЧЕТ!C5*0.2,C5+ОТЧЕТ!C5*0.15) -> 741.75 | F5: Ямало-Ненецкий АО, г Новый Уренгой, ул Заречная, д 2А | G5: 5903072982 | H5: Аптека;сайт:www.planetazdorovo.ru | I5: =INDEX('Справочник Сети'!B:B,(MATCH(G5,'Справочник Сети'!C:C,0))) -> Планета здоровья | J5: 2025-02-24 | K5: 15:12:00 | L5: 2025-02-24 | M5: 45712 | N5: 15:14:58 | O5: 1253 | P5: 88 | Q5: =IF(COUNTIFS(A$2:A5,A5,I$2:I5,I5)=1,1,0) -> 1 | R5: =COUNTIF(O:O,O5) -> 8 | S5: =IF(COUNTIF(O$2:O5,O5)=1,R5,0)/2.5 -> 3.2 | U5: SKU4 | V5: =SUMIF(A:A,U5,B:B) -> 4 | W5: =SUMPRODUCT(--(A:A=U5),B:B,C:C) -> 1524 | X5: =SUMIF(A:A,U5,Q:Q) -> 2
A6: SKU1 | B6: 1 | C6: 308 | D6: =C6+IF(INDEX('Справочник по %'!B:B,(MATCH(A6,'Справочник по %'!A:A,0)))="кол-во",B6*INDEX('Справочник по %'!C:C,(MATCH(A6,'Справочник по %'!A:A,0))),ОТЧЕТ!C6*INDEX('Справочник по %'!C:C,(MATCH(A6,'Справочник по %'!A:A,0))))/100 -> 338.8 | E6: =IF(ОТЧЕТ!A6="SKU3",C6+ОТЧЕТ!C6*0.2,C6+ОТЧЕТ!C6*0.15) -> 354.2 | F6: Ямало-Ненецкий АО, г Новый Уренгой, ул Заречная, д 2А | G6: 2308209785 | H6: Аптека | I6: =INDEX('Справочник Сети'!B:B,(MATCH(G6,'Справочник Сети'!C:C,0))) -> Планета здоровья | J6: 2025-03-13 | K6: 15:21:00 | L6: 2025-03-13 | M6: 45729 | N6: 15:25:09 | O6: 925 | P6: 91 | Q6: =IF(COUNTIFS(A$2:A6,A6,I$2:I6,I6)=1,1,0) -> 1 | R6: =COUNTIF(O:O,O6) -> 1 | S6: =IF(COUNTIF(O$2:O6,O6)=1,R6,0)/2.5 -> 0.4
A7: SKU1 | B7: 1 | C7: 442 | D7: =C7+IF(INDEX('Справочник по %'!B:B,(MATCH(A7,'Справочник по %'!A:A,0)))="кол-во",B7*INDEX('Справочник по %'!C:C,(MATCH(A7,'Справочник по %'!A:A,0))),ОТЧЕТ!C7*INDEX('Справочник по %'!C:C,(MATCH(A7,'Справочник по %'!A:A,0))))/100 -> 486.2 | E7: =IF(ОТЧЕТ!A7="SKU3",C7+ОТЧЕТ!C7*0.2,C7+ОТЧЕТ!C7*0.15) -> 508.3 | F7: Ямало-Ненецкий АО, г Новый Уренгой, ул 26 Съезда КПСС, д 4В | G7: 2310052764 | H7: Аптека № 508 | I7: =INDEX('Справочник Сети'!B:B,(MATCH(G7,'Справочник Сети'!C:C,0))) -> Планета здоровья | J7: 2025-03-13 | K7: 15:16:00 | L7: 2025-03-13 | M7: 45729 | N7: 15:29:30 | O7: 2557 | P7: 92 | Q7: =IF(COUNTIFS(A$2:A7,A7,I$2:I7,I7)=1,1,0) -> 0 | R7: =COUNTIF(O:O,O7) -> 1 | S7: =IF(COUNTIF(O$2:O7,O7)=1,R7,0)/2.5 -> 0.4
A8: SKU1 | B8: 1 | C8: 426.4 | D8: =C8+IF(INDEX('Справочник по %'!B:B,(MATCH(A8,'Справочник по %'!A:A,0)))="кол-во",B8*INDEX('Справочник по %'!C:C,(MATCH(A8,'Справочник по %'!A:A,0))),ОТЧЕТ!C8*INDEX('Справочник по %'!C:C,(MATCH(A8,'Справочник по %'!A:A,0))))/100 -> 469.04 | E8: =IF(ОТЧЕТ!A8="SKU3",C8+ОТЧЕТ!C8*0.2,C8+ОТЧЕТ!C8*0.15) -> 490.36 | F8: Ямало-Ненецкий АО, г Новый Уренгой, ул 26 Съезда КПСС, д 4В | G8: 3704004871 | H8: аптека | I8: =INDEX('Справочник Сети'!B:B,(MATCH(G8,'Справочник Сети'!C:C,0))) -> Планета здоровья | J8: 2025-03-01 | K8: 15:26:00 | L8: 2025-03-01 | M8: 45717 | N8: 15:31:19 | O8: 3489 | P8: 93 | Q8: =IF(COUNTIFS(A$2:A8,A8,I$2:I8,I8)=1,1,0) -> 0 | R8: =COUNTIF(O:O,O8) -> 6 | S8: =IF(COUNTIF(O$2:O8,O8)=1,R8,0)/2.5 -> 2.4
A9: SKU2 | B9: 1 | C9: 582 | D9: =C9+IF(INDEX('Справочник по %'!B:B,(MATCH(A9,'Справочник по %'!A:A,0)))="кол-во",B9*INDEX('Справочник по %'!C:C,(MATCH(A9,'Справочник по %'!A:A,0))),ОТЧЕТ!C9*INDEX('Справочник по %'!C:C,(MATCH(A9,'Справочник по %'!A:A,0))))/100 -> 582.2 | E9: =IF(ОТЧЕТ!A9="SKU3",C9+ОТЧЕТ!C9*0.2,C9+ОТЧЕТ!C9*0.15) -> 669.3 | F9: Ямало-Ненецкий АО, г Новый Уренгой, пр-кт Губкина, д 19 | G9: 2310200444 | H9: Торговый зал | I9: =INDEX('Справочник Сети'!B:B,(MATCH(G9,'Справочник Сети'!C:C,0))) -> Планета здоровья | J9: 2025-03-12 | K9: 15:38:00 | L9: 2025-03-13 | M9: 45729 | N9: 15:41:20 | O9: 548 | P9: 99 | Q9: =IF(COUNTIFS(A$2:A9,A9,I$2:I9,I9)=1,1,0) -> 0 | R9: =COUNTIF(O:O,O9) -> 4 | S9: =IF(COUNTIF(O$2:O9,O9)=1,R9,0)/2.5 -> 1.6
A10: SKU1 | B10: 1 | C10: 478 | D10: =C10+IF(INDEX('Справочник по %'!B:B,(MATCH(A10,'Справочник по %'!A:A,0)))="кол-во",B10*INDEX('Справочник по %'!C:C,(MATCH(A10,'Справочник по %'!A:A,0))),ОТЧЕТ!C10*INDEX('Справочник по %'!C:C,(MATCH(A10,'Справочник по %'!A:A,0))))/100 -> 525.8 | E10: =IF(ОТЧЕТ!A10="SKU3",C10+ОТЧЕТ!C10*0.2,C10+ОТЧЕТ!C10*0.15) -> 549.7 | F10: Ямало-Ненецкий АО, г Новый Уренгой, пр-кт Губкина, д 19 | G10: 9726023519 | H10: Мск Аптека 80 127576, Москва г, Череповецкая ул, дом № 18 | I10: =INDEX('Справочник Сети'!B:B,(MATCH(G10,'Справочник Сети'!C:C,0))) -> Планета здоровья | J10: 2025-01-04 | K10: 15:47:00 | L10: 2025-01-04 | M10: 45661 | N10: 15:47:23 | O10: 2375 | P10: 100 | Q10: =IF(COUNTIFS(A$2:A10,A10,I$2:I10,I10)=1,1,0) -> 0 | R10: =COUNTIF(O:O,O10) -> 1 | S10: =IF(COUNTIF(O$2:O10,O10)=1,R10,0)/2.5 -> 0.4
A11: SKU1 | B11: 1 | C11: 440 | D11: =C11+IF(INDEX('Справочник по %'!B:B,(MATCH(A11,'Справочник по %'!A:A,0)))="кол-во",B11*INDEX('Справочник по %'!C:C,(MATCH(A11,'Справочник по %'!A:A,0))),ОТЧЕТ!C11*INDEX('Справочник по %'!C:C,(MATCH(A11,'Справочник по %'!A:A,0))))/100 -> 484 | E11: =IF(ОТЧЕТ!A11="SKU3",C11+ОТЧЕТ!C11*0.2,C11+ОТЧЕТ!C11*0.15) -> 506 | F11: Ямало-Ненецкий АО, г Новый Уренгой, пр-кт Губкина, д 19 | G11: 231705666100 | H11: Аптека | I11: =INDEX('Справочник Сети'!B:B,(MATCH(G11,'Справочник Сети'!C:C,0))) -> Планета здоровья | J11: 2025-01-04 | K11: 15:52:00 | L11: 2025-01-04 | M11: 45661 | N11: 15:52:29 | O11: 841 | P11: 102 | Q11: =IF(COUNTIFS(A$2:A11,A11,I$2:I11,I11)=1,1,0) -> 0 | R11: =COUNTIF(O:O,O11) -> 4 | S11: =IF(COUNTIF(O$2:O11,O11)=1,R11,0)/2.5 -> 1.6
A12: SKU1 | B12: 1 | C12: 399 | D12: =C12+IF(INDEX('Справочник по %'!B:B,(MATCH(A12,'Справочник по %'!A:A,0)))="кол-во",B12*INDEX('Справочник по %'!C:C,(MATCH(A12,'Справочник по %'!A:A,0))),ОТЧЕТ!C12*INDEX('Справочник по %'!C:C,(MATCH(A12,'Справочник по %'!A:A,0))))/100 -> 438.9 | E12: =IF(ОТЧЕТ!A12="SKU3",C12+ОТЧЕТ!C12*0.2,C12+ОТЧЕТ!C12*0.15) -> 458.85 | F12: Ямало-Ненецкий АО, г Новый Уренгой, пр-кт Губкина, д 19 | G12: 5906086550 | H12: Аптека;сайт:www.planetazdorovo.ru | I12: =INDEX('Справочник Сети'!B:B,(MATCH(G12,'Справочник Сети'!C:C,0))) -> Планета здоровья | J12: 2025-02-22 | K12: 15:45:00 | L12: 2025-02-24 | M12: 45712 | N12: 15:57:49 | O12: 3609 | P12: 105 | Q12: =IF(COUNTIFS(A$2:A12,A12,I$2:I12,I12)=1,1,0) -> 0 | R12: =COUNTIF(O:O,O12) -> 2 | S12: =IF(COUNTIF(O$2:O12,O12)=1,R12,0)/2.5 -> 0.8
A13: SKU2 | B13: 1 | C13: 683 | D13: =C13+IF(INDEX('Справочник по %'!B:B,(MATCH(A13,'Справочник по %'!A:A,0)))="кол-во",B13*INDEX('Справочник по %'!C:C,(MATCH(A13,'Справочник по %'!A:A,0))),ОТЧЕТ!C13*INDEX('Справочник по %'!C:C,(MATCH(A13,'Справочник по %'!A:A,0))))/100 -> 683.2 | E13: =IF(ОТЧЕТ!A13="SKU3",C13+ОТЧЕТ!C13*0.2,C13+ОТЧЕТ!C13*0.15) -> 785.45 | F13: Ямало-Ненецкий АО, г Новый Уренгой, мкр Тундровый, д 3 | G13: 4705071640 | H13: Аптека | I13: =INDEX('Справочник Сети'!B:B,(MATCH(G13,'Справочник Сети'!C:C,0))) -> Планета здоровья | J13: 2025-02-27 | K13: 15:41:00 | L13: 2025-02-27 | M13: 45715 | N13: 16:01:12 | O13: 1467 | P13: 107 | Q13: =IF(COUNTIFS(A$2:A13,A13,I$2:I13,I13)=1,1,0) -> 0 | R13: =COUNTIF(O:O,O13) -> 1 | S13: =IF(COUNTIF(O$2:O13,O13)=1,R13,0)/2.5 -> 0.4
A14: SKU2 | B14: 1 | C14: 538 | D14: =C14+IF(INDEX('Справочник по %'!B:B,(MATCH(A14,'Справочник по %'!A:A,0)))="кол-во",B14*INDEX('Справочник по %'!C:C,(MATCH(A14,'Справочник по %'!A:A,0))),ОТЧЕТ!C14*INDEX('Справочник по %'!C:C,(MATCH(A14,'Справочник по %'!A:A,0))))/100 -> 538.2 | E14: =IF(ОТЧЕТ!A14="SKU3",C14+ОТЧЕТ!C14*0.2,C14+ОТЧЕТ!C14*0.15) -> 618.7 | F14: Ямало-Ненецкий АО, г Новый Уренгой, мкр Тундровый, д 3 | G14: 7706795062 | H14: Аптечный пункт-АФ-(Мск)-Войковская-1 | I14: =INDEX('Справочник Сети'!B:B,(MATCH(G14,'Справочник Сети'!C:C,0))) -> Планета здоровья | J14: 2025-02-03 | K14: 16:02:00 | L14: 2025-02-03 | M14: 45691 | N14: 16:03:08 | O14: 3349 | P14: 108 | Q14: =IF(COUNTIFS(A$2:A14,A14,I$2:I14,I14)=1,1,0) -> 0 | R14: =COUNTIF(O:O,O14) -> 5 | S14: =IF(COUNTIF(O$2:O14,O14)=1,R14,0)/2.5 -> 2
A15: SKU1 | B15: 1 | C15: 540 | D15: =C15+IF(INDEX('Справочник по %'!B:B,(MATCH(A15,'Справочник по %'!A:A,0)))="кол-во",B15*INDEX('Справочник по %'!C:C,(MATCH(A15,'Справочник по %'!A:A,0))),ОТЧЕТ!C15*INDEX('Справочник по %'!C:C,(MATCH(A15,'Справочник по %'!A:A,0))))/100 -> 594 | E15: =IF(ОТЧЕТ!A15="SKU3",C15+ОТЧЕТ!C15*0.2,C15+ОТЧЕТ!C15*0.15) -> 621 | F15: Ямало-Ненецкий АО, г Новый Уренгой, мкр Советский, д 6 к 3 | G15: 5032223231 | H15: Аптечный пункт | I15: =INDEX('Справочник Сети'!B:B,(MATCH(G15,'Справочник Сети'!C:C,0))) -> Планета здоровья | J15: 2025-02-26 | K15: 15:11:00 | L15: 2025-02-26 | M15: 45714 | N15: 16:14:47 | O15: 594 | P15: 114 | Q15: =IF(COUNTIFS(A$2:A15,A15,I$2:I15,I15)=1,1,0) -> 0 | R15: =COUNTIF(O:O,O15) -> 2 | S15: =IF(COUNTIF(O$2:O15,O15)=1,R15,0)/2.5 -> 0.8
A16: SKU1 | B16: 1 | C16: 463 | D16: =C16+IF(INDEX('Справочник по %'!B:B,(MATCH(A16,'Справочник по %'!A:A,0)))="кол-во",B16*INDEX('Справочник по %'!C:C,(MATCH(A16,'Справочник по %'!A:A,0))),ОТЧЕТ!C16*INDEX('Справочник по %'!C:C,(MATCH(A16,'Справочник по %'!A:A,0))))/100 -> 509.3 | E16: =IF(ОТЧЕТ!A16="SKU3",C16+ОТЧЕТ!C16*0.2,C16+ОТЧЕТ!C16*0.15) -> 532.45 | F16: Ямало-Ненецкий АО, г Новый Уренгой, мкр Советский, д 6 к 3 | G16: 2373007595 | H16: Аптека № 217 | I16: =INDEX('Справочник Сети'!B:B,(MATCH(G16,'Справочник Сети'!C:C,0))) -> Планета здоровья | J16: 2025-03-11 | K16: 16:29:00 | L16: 2025-03-11 | M16: 45727 | N16: 16:33:38 | O16: 3796 | P16: 123 | Q16: =IF(COUNTIFS(A$2:A16,A16,I$2:I16,I16)=1,1,0) -> 0 | R16: =COUNTIF(O:O,O16) -> 1 | S16: =IF(COUNTIF(O$2:O16,O16)=1,R16,0)/2.5 -> 0.4
A17: SKU1 | B17: 1 | C17: 394 | D17: =C17+IF(INDEX('Справочник по %'!B:B,(MATCH(A17,'Справочник по %'!A:A,0)))="кол-во",B17*INDEX('Справочник по %'!C:C,(MATCH(A17,'Справочник по %'!A:A,0))),ОТЧЕТ!C17*INDEX('Справочник по %'!C:C,(MATCH(A17,'Справочник по %'!A:A,0))))/100 -> 433.4 | E17: =IF(ОТЧЕТ!A17="SKU3",C17+ОТЧЕТ!C17*0.2,C17+ОТЧЕТ!C17*0.15) -> 453.1 | F17: Ямало-Ненецкий АО, г Новый Уренгой, мкр Советский, д 6 к 3 | G17: 7706795062 | H17: Аптечный пункт-ТФ-(Мск)-Строгино-1 | I17: =INDEX('Справочник Сети'!B:B,(MATCH(G17,'Справочник Сети'!C:C,0))) -> Планета здоровья | J17: 2025-02-03 | K17: 16:35:00 | L17: 2025-02-03 | M17: 45691 | N17: 16:35:08 | O17: 3604 | P17: 124 | Q17: =IF(COUNTIFS(A$2:A17,A17,I$2:I17,I17)=1,1,0) -> 0 | R17: =COUNTIF(O:O,O17) -> 3 | S17: =IF(COUNTIF(O$2:O17,O17)=1,R17,0)/2.5 -> 1.2
... A128: SKU2 | B128: 1 | C128: 570 | D128: =C128+IF(INDEX('Справочник по %'!B:B,(MATCH(A128,'Справочник по %'!A:A,0)))="кол-во",B128*INDEX('Справочник по %'!C:C,(MATCH(A128,'Справочник по %'!A:A,0))),ОТЧЕТ!C128*INDEX('Справочник по %'!C:C,(MATCH(A128,'Справочник по %'!A:A,0))))/100 -> 570.2 | E128: =IF(ОТЧЕТ!A128="SKU3",C128+ОТЧЕТ!C128*0.2,C128+ОТЧЕТ!C128*0.15) -> 655.5 | F128: Ставропольский край, г Михайловск, ул Вокзальная, влд 121 | G128: 2310200444 | H128: Торговый зал | I128: =INDEX('Справочник Сети'!B:B,(MATCH(G128,'Справочник Сети'!C:C,0))) -> Планета здоровья | J128: 2025-03-12 | K128: 09:13:00 | L128: 2025-03-13 | M128: 45729 | N128: 20:44:38 | O128: 1345 | P128: 1086 | Q128: =IF(COUNTIFS(A$2:A128,A128,I$2:I128,I128)=1,1,0) -> 0 | R128: =COUNTIF(O:O,O128) -> 1 | S128: =IF(COUNTIF(O$2:O128,O128)=1,R128,0)/2.5 -> 0.4
A129: SKU1 | B129: 1 | C129: 400 | D129: =C129+IF(INDEX('Справочник по %'!B:B,(MATCH(A129,'Справочник по %'!A:A,0)))="кол-во",B129*INDEX('Справочник по %'!C:C,(MATCH(A129,'Справочник по %'!A:A,0))),ОТЧЕТ!C129*INDEX('Справочник по %'!C:C,(MATCH(A129,'Справочник по %'!A:A,0))))/100 -> 440 | E129: =IF(ОТЧЕТ!A129="SKU3",C129+ОТЧЕТ!C129*0.2,C129+ОТЧЕТ!C129*0.15) -> 460 | F129: Ставропольский край, г Михайловск, ул Войкова, зд 393 | G129: 3821001306 | H129: 666034.Иркутская обл. г. Шелехов 8 квартал дом 13 | I129: =INDEX('Справочник Сети'!B:B,(MATCH(G129,'Справочник Сети'!C:C,0))) -> #N/A | J129: 2025-02-28 | K129: 01:40:00 | L129: 2025-02-28 | M129: 45716 | N129: 20:44:53 | O129: 3709 | P129: 1087 | Q129: =IF(COUNTIFS(A$2:A129,A129,I$2:I129,I129)=1,1,0) -> 1 | R129: =COUNTIF(O:O,O129) -> 5 | S129: =IF(COUNTIF(O$2:O129,O129)=1,R129,0)/2.5 -> 2
A130: SKU1 | B130: 1 | C130: 490 | D130: =C130+IF(INDEX('Справочник по %'!B:B,(MATCH(A130,'Справочник по %'!A:A,0)))="кол-во",B130*INDEX('Справочник по %'!C:C,(MATCH(A130,'Справочник по %'!A:A,0))),ОТЧЕТ!C130*INDEX('Справочник по %'!C:C,(MATCH(A130,'Справочник по %'!A:A,0))))/100 -> 539 | E130: =IF(ОТЧЕТ!A130="SKU3",C130+ОТЧЕТ!C130*0.2,C130+ОТЧЕТ!C130*0.15) -> 563.5 | F130: Ставропольский край, г Михайловск, ул Войкова, д 391 | G130: 7814809234 | H130: Аптека "РИГЛА" | I130: =INDEX('Справочник Сети'!B:B,(MATCH(G130,'Справочник Сети'!C:C,0))) -> 0 | J130: 2025-01-14 | K130: 19:15:00 | L130: 2025-01-14 | M130: 45671 | N130: 20:45:19 | O130: 3329 | P130: 1088 | Q130: =IF(COUNTIFS(A$2:A130,A130,I$2:I130,I130)=1,1,0) -> 1 | R130: =COUNTIF(O:O,O130) -> 1 | S130: =IF(COUNTIF(O$2:O130,O130)=1,R130,0)/2.5 -> 0.4
A131: SKU1 | B131: 1 | C131: 338.92 | D131: =C131+IF(INDEX('Справочник по %'!B:B,(MATCH(A131,'Справочник по %'!A:A,0)))="кол-во",B131*INDEX('Справочник по %'!C:C,(MATCH(A131,'Справочник по %'!A:A,0))),ОТЧЕТ!C131*INDEX('Справочник по %'!C:C,(MATCH(A131,'Справочник по %'!A:A,0))))/100 -> 372.812 | E131: =IF(ОТЧЕТ!A131="SKU3",C131+ОТЧЕТ!C131*0.2,C131+ОТЧЕТ!C131*0.15) -> 389.758 | F131: Ставропольский край, г Минеральные Воды, пр-кт 22 Партсъезда, стр 86/1 | G131: 7732121736 | H131: Аптечный пункт №77-404 | I131: =INDEX('Справочник Сети'!B:B,(MATCH(G131,'Справочник Сети'!C:C,0))) -> Планета здоровья | J131: 2025-01-16 | K131: 14:10:00 | L131: 2025-01-16 | M131: 45673 | N131: 20:49:38 | O131: 2740 | P131: 1093 | Q131: =IF(COUNTIFS(A$2:A131,A131,I$2:I131,I131)=1,1,0) -> 0 | R131: =COUNTIF(O:O,O131) -> 1 | S131: =IF(COUNTIF(O$2:O131,O131)=1,R131,0)/2.5 -> 0.4
A132: SKU1 | B132: 1 | C132: 440 | D132: =C132+IF(INDEX('Справочник по %'!B:B,(MATCH(A132,'Справочник по %'!A:A,0)))="кол-во",B132*INDEX('Справочник по %'!C:C,(MATCH(A132,'Справочник по %'!A:A,0))),ОТЧЕТ!C132*INDEX('Справочник по %'!C:C,(MATCH(A132,'Справочник по %'!A:A,0))))/100 -> 484 | E132: =IF(ОТЧЕТ!A132="SKU3",C132+ОТЧЕТ!C132*0.2,C132+ОТЧЕТ!C132*0.15) -> 506 | F132: Ставропольский край, г Минеральные Воды, пр-кт 22 Партсъезда, стр 86/1 | G132: 462901346416 | H132: Аптека | I132: =INDEX('Справочник Сети'!B:B,(MATCH(G132,'Справочник Сети'!C:C,0))) -> Планета здоровья | J132: 2025-01-03 | K132: 19:28:00 | L132: 2025-01-03 | M132: 45660 | N132: 20:50:10 | O132: 347 | P132: 1094 | Q132: =IF(COUNTIFS(A$2:A132,A132,I$2:I132,I132)=1,1,0) -> 0 | R132: =COUNTIF(O:O,O132) -> 4 | S132: =IF(COUNTIF(O$2:O132,O132)=1,R132,0)/2.5 -> 1.6
A133: SKU1 | B133: 1 | C133: 470 | D133: =C133+IF(INDEX('Справочник по %'!B:B,(MATCH(A133,'Справочник по %'!A:A,0)))="кол-во",B133*INDEX('Справочник по %'!C:C,(MATCH(A133,'Справочник по %'!A:A,0))),ОТЧЕТ!C133*INDEX('Справочник по %'!C:C,(MATCH(A133,'Справочник по %'!A:A,0))))/100 -> 517 | E133: =IF(ОТЧЕТ!A133="SKU3",C133+ОТЧЕТ!C133*0.2,C133+ОТЧЕТ!C133*0.15) -> 540.5 | F133: Ставропольский край, г Минеральные Воды, пр-кт 22 Партсъезда, зд 137/1 | G133: 5903072982 | H133: Аптека;сайт:www.planetazdorovo.ru | I133: =INDEX('Справочник Сети'!B:B,(MATCH(G133,'Справочник Сети'!C:C,0))) -> Планета здоровья | J133: 2025-02-24 | K133: 20:21:00 | L133: 2025-02-24 | M133: 45712 | N133: 21:02:20 | O133: 452 | P133: 1104 | Q133: =IF(COUNTIFS(A$2:A133,A133,I$2:I133,I133)=1,1,0) -> 0 | R133: =COUNTIF(O:O,O133) -> 1 | S133: =IF(COUNTIF(O$2:O133,O133)=1,R133,0)/2.5 -> 0.4
A134: SKU1 | B134: 1 | C134: 439 | D134: =C134+IF(INDEX('Справочник по %'!B:B,(MATCH(A134,'Справочник по %'!A:A,0)))="кол-во",B134*INDEX('Справочник по %'!C:C,(MATCH(A134,'Справочник по %'!A:A,0))),ОТЧЕТ!C134*INDEX('Справочник по %'!C:C,(MATCH(A134,'Справочник по %'!A:A,0))))/100 -> 482.9 | E134: =IF(ОТЧЕТ!A134="SKU3",C134+ОТЧЕТ!C134*0.2,C134+ОТЧЕТ!C134*0.15) -> 504.85 | F134: Ставропольский край, г Минеральные Воды, пр-кт 22 Партсъезда, д 141 | G134: 6659049231 | H134: Аптека "ЛИА" | I134: =INDEX('Справочник Сети'!B:B,(MATCH(G134,'Справочник Сети'!C:C,0))) -> 0 | J134: 2025-02-07 | K134: 23:07:00 | L134: 2025-02-07 | M134: 45695 | N134: 21:12:57 | O134: 3056 | P134: 1106 | Q134: =IF(COUNTIFS(A$2:A134,A134,I$2:I134,I134)=1,1,0) -> 0 | R134: =COUNTIF(O:O,O134) -> 1 | S134: =IF(COUNTIF(O$2:O134,O134)=1,R134,0)/2.5 -> 0.4
A135: SKU1 | B135: 1 | C135: 390 | D135: =C135+IF(INDEX('Справочник по %'!B:B,(MATCH(A135,'Справочник по %'!A:A,0)))="кол-во",B135*INDEX('Справочник по %'!C:C,(MATCH(A135,'Справочник по %'!A:A,0))),ОТЧЕТ!C135*INDEX('Справочник по %'!C:C,(MATCH(A135,'Справочник по %'!A:A,0))))/100 -> 429 | E135: =IF(ОТЧЕТ!A135="SKU3",C135+ОТЧЕТ!C135*0.2,C135+ОТЧЕТ!C135*0.15) -> 448.5 | F135: Ставропольский край, г Лермонтов, ул Патриса Лумумбы, д 33 | G135: 2373007348 | H135: Аптека №15 | I135: =INDEX('Справочник Сети'!B:B,(MATCH(G135,'Справочник Сети'!C:C,0))) -> 0 | J135: 2025-03-11 | K135: 10:44:00 | L135: 2025-03-11 | M135: 45727 | N135: 21:35:51 | O135: 1173 | P135: 1110 | Q135: =IF(COUNTIFS(A$2:A135,A135,I$2:I135,I135)=1,1,0) -> 0 | R135: =COUNTIF(O:O,O135) -> 2 | S135: =IF(COUNTIF(O$2:O135,O135)=1,R135,0)/2.5 -> 0.8
A136: SKU1 | B136: 1 | C136: 541 | D136: =C136+IF(INDEX('Справочник по %'!B:B,(MATCH(A136,'Справочник по %'!A:A,0)))="кол-во",B136*INDEX('Справочник по %'!C:C,(MATCH(A136,'Справочник по %'!A:A,0))),ОТЧЕТ!C136*INDEX('Справочник по %'!C:C,(MATCH(A136,'Справочник по %'!A:A,0))))/100 -> 595.1 | E136: =IF(ОТЧЕТ!A136="SKU3",C136+ОТЧЕТ!C136*0.2,C136+ОТЧЕТ!C136*0.15) -> 622.15 | F136: Ставропольский край, г Кисловодск, ул Российская, д 5 | G136: 5260408672 | H136: Аптека | I136: =INDEX('Справочник Сети'!B:B,(MATCH(G136,'Справочник Сети'!C:C,0))) -> 0 | J136: 2025-02-26 | K136: 21:33:00 | L136: 2025-02-26 | M136: 45714 | N136: 21:45:27 | O136: 2298 | P136: 1114 | Q136: =IF(COUNTIFS(A$2:A136,A136,I$2:I136,I136)=1,1,0) -> 0 | R136: =COUNTIF(O:O,O136) -> 1 | S136: =IF(COUNTIF(O$2:O136,O136)=1,R136,0)/2.5 -> 0.4
A137: SKU1 | B137: 1 | C137: 424 | D137: =C137+IF(INDEX('Справочник по %'!B:B,(MATCH(A137,'Справочник по %'!A:A,0)))="кол-во",B137*INDEX('Справочник по %'!C:C,(MATCH(A137,'Справочник по %'!A:A,0))),ОТЧЕТ!C137*INDEX('Справочник по %'!C:C,(MATCH(A137,'Справочник по %'!A:A,0))))/100 -> 466.4 | E137: =IF(ОТЧЕТ!A137="SKU3",C137+ОТЧЕТ!C137*0.2,C137+ОТЧЕТ!C137*0.15) -> 487.6 | F137: Ставропольский край, г Кисловодск, ул Кутузова, зд 83А | G137: 2466189073 | H137: Филиал 3 ЦРА 123 | I137: =INDEX('Справочник Сети'!B:B,(MATCH(G137,'Справочник Сети'!C:C,0))) -> Нео-фарм | J137: 2025-03-11 | K137: 00:24:00 | L137: 2025-03-11 | M137: 45727 | N137: 21:46:13 | O137: 3749 | P137: 1115 | Q137: =IF(COUNTIFS(A$2:A137,A137,I$2:I137,I137)=1,1,0) -> 0 | R137: =COUNTIF(O:O,O137) -> 1 | S137: =IF(COUNTIF(O$2:O137,O137)=1,R137,0)/2.5 -> 0.4
A138: SKU1 | B138: 1 | C138: 370 | D138: =C138+IF(INDEX('Справочник по %'!B:B,(MATCH(A138,'Справочник по %'!A:A,0)))="кол-во",B138*INDEX('Справочник по %'!C:C,(MATCH(A138,'Справочник по %'!A:A,0))),ОТЧЕТ!C138*INDEX('Справочник по %'!C:C,(MATCH(A138,'Справочник по %'!A:A,0))))/100 -> 407 | E138: =IF(ОТЧЕТ!A138="SKU3",C138+ОТЧЕТ!C138*0.2,C138+ОТЧЕТ!C138*0.15) -> 425.5 | F138: Ставропольский край, г Кисловодск, ул Кутузова, зд 83А | G138: 2225105670 | H138: Торговый зал | I138: =INDEX('Справочник Сети'!B:B,(MATCH(G138,'Справочник Сети'!C:C,0))) -> Столички | J138: 2025-03-14 | K138: 11:31:00 | L138: 2025-03-14 | M138: 45730 | N138: 07:35:46 | O138: 2919 | P138: 1118 | Q138: =IF(COUNTIFS(A$2:A138,A138,I$2:I138,I138)=1,1,0) -> 0 | R138: =COUNTIF(O:O,O138) -> 8 | S138: =IF(COUNTIF(O$2:O138,O138)=1,R138,0)/2.5 -> 3.2
A139: SKU1 | B139: 1 | C139: 553 | D139: =C139+IF(INDEX('Справочник по %'!B:B,(MATCH(A139,'Справочник по %'!A:A,0)))="кол-во",B139*INDEX('Справочник по %'!C:C,(MATCH(A139,'Справочник по %'!A:A,0))),ОТЧЕТ!C139*INDEX('Справочник по %'!C:C,(MATCH(A139,'Справочник по %'!A:A,0))))/100 -> 608.3 | E139: =IF(ОТЧЕТ!A139="SKU3",C139+ОТЧЕТ!C139*0.2,C139+ОТЧЕТ!C139*0.15) -> 635.95 | F139: Ставропольский край, г Кисловодск, ул Кутузова, зд 83А | G139: 5405072034 | H139: NSK-MZ13-SRV | I139: =INDEX('Справочник Сети'!B:B,(MATCH(G139,'Справочник Сети'!C:C,0))) -> Нео-фарм | J139: 2025-02-26 | K139: 13:30:00 | L139: 2025-02-26 | M139: 45714 | N139: 09:55:26 | O139: 2903 | P139: 1119 | Q139: =IF(COUNTIFS(A$2:A139,A139,I$2:I139,I139)=1,1,0) -> 0 | R139: =COUNTIF(O:O,O139) -> 1 | S139: =IF(COUNTIF(O$2:O139,O139)=1,R139,0)/2.5 -> 0.4
A140: SKU1 | B140: 1 | C140: 451 | D140: =C140+IF(INDEX('Справочник по %'!B:B,(MATCH(A140,'Справочник по %'!A:A,0)))="кол-во",B140*INDEX('Справочник по %'!C:C,(MATCH(A140,'Справочник по %'!A:A,0))),ОТЧЕТ!C140*INDEX('Справочник по %'!C:C,(MATCH(A140,'Справочник по %'!A:A,0))))/100 -> 496.1 | E140: =IF(ОТЧЕТ!A140="SKU3",C140+ОТЧЕТ!C140*0.2,C140+ОТЧЕТ!C140*0.15) -> 518.65 | F140: Ставропольский край, г Кисловодск, ул Куйбышева, д 66 | G140: 326537584 | H140: Аптека, ул. Краснофлотская, 36А | I140: =INDEX('Справочник Сети'!B:B,(MATCH(G140,'Справочник Сети'!C:C,0))) -> Планета здоровья | J140: 2025-03-16 | K140: 13:50:00 | L140: 2025-03-16 | M140: 45732 | N140: 08:49:54 | O140: 1702 | P140: 1122 | Q140: =IF(COUNTIFS(A$2:A140,A140,I$2:I140,I140)=1,1,0) -> 0 | R140: =COUNTIF(O:O,O140) -> 9 | S140: =IF(COUNTIF(O$2:O140,O140)=1,R140,0)/2.5 -> 0
A141: SKU1 | B141: 1 | C141: 385.9 | D141: =C141+IF(INDEX('Справочник по %'!B:B,(MATCH(A141,'Справочник по %'!A:A,0)))="кол-во",B141*INDEX('Справочник по %'!C:C,(MATCH(A141,'Справочник по %'!A:A,0))),ОТЧЕТ!C141*INDEX('Справочник по %'!C:C,(MATCH(A141,'Справочник по %'!A:A,0))))/100 -> 424.49 | E141: =IF(ОТЧЕТ!A141="SKU3",C141+ОТЧЕТ!C141*0.2,C141+ОТЧЕТ!C141*0.15) -> 443.785 | F141: Ставропольский край, г Кисловодск, ул Куйбышева, д 66 | G141: 3801042576 | H141: аптека | I141: =INDEX('Справочник Сети'!B:B,(MATCH(G141,'Справочник Сети'!C:C,0))) -> Планета здоровья | J141: 2025-03-01 | K141: 15:36:00 | L141: 2025-03-01 | M141: 45717 | N141: 10:40:53 | O141: 2531 | P141: 1125 | Q141: =IF(COUNTIFS(A$2:A141,A141,I$2:I141,I141)=1,1,0) -> 0 | R141: =COUNTIF(O:O,O141) -> 5 | S141: =IF(COUNTIF(O$2:O141,O141)=1,R141,0)/2.5 -> 2
A142: SKU2 | B142: 1 | C142: 634 | D142: =C142+IF(INDEX('Справочник по %'!B:B,(MATCH(A142,'Справочник по %'!A:A,0)))="кол-во",B142*INDEX('Справочник по %'!C:C,(MATCH(A142,'Справочник по %'!A:A,0))),ОТЧЕТ!C142*INDEX('Справочник по %'!C:C,(MATCH(A142,'Справочник по %'!A:A,0))))/100 -> 634.2 | E142: =IF(ОТЧЕТ!A142="SKU3",C142+ОТЧЕТ!C142*0.2,C142+ОТЧЕТ!C142*0.15) -> 729.1 | F142: Ставропольский край, г Кисловодск, ул Куйбышева, д 66 | G142: 7720588903 | H142: Аптечный пункт "ТРИКА" | I142: =INDEX('Справочник Сети'!B:B,(MATCH(G142,'Справочник Сети'!C:C,0))) -> #N/A | J142: 2025-01-18 | K142: 22:01:00 | L142: 2025-01-19 | M142: 45676 | N142: 22:02:42 | O142: 3481 | P142: 1128 | Q142: =IF(COUNTIFS(A$2:A142,A142,I$2:I142,I142)=1,1,0) -> 1 | R142: =COUNTIF(O:O,O142) -> 1 | S142: =IF(COUNTIF(O$2:O142,O142)=1,R142,0)/2.5 -> 0.4
A143: SKU1 | B143: 1 | C143: 557 | D143: =C143+IF(INDEX('Справочник по %'!B:B,(MATCH(A143,'Справочник по %'!A:A,0)))="кол-во",B143*INDEX('Справочник по %'!C:C,(MATCH(A143,'Справочник по %'!A:A,0))),ОТЧЕТ!C143*INDEX('Справочник по %'!C:C,(MATCH(A143,'Справочник по %'!A:A,0))))/100 -> 612.7 | E143: =IF(ОТЧЕТ!A143="SKU3",C143+ОТЧЕТ!C143*0.2,C143+ОТЧЕТ!C143*0.15) -> 640.55 | F143: Ставропольский край, г Кисловодск, ул Куйбышева, д 66 | G143: 2309136755 | H143: Аптека | I143: =INDEX('Справочник Сети'!B:B,(MATCH(G143,'Справочник Сети'!C:C,0))) -> Столички | J143: 2025-03-13 | K143: 21:47:00 | L143: 2025-03-13 | M143: 45729 | N143: 22:06:48 | O143: 1577 | P143: 1130 | Q143: =IF(COUNTIFS(A$2:A143,A143,I$2:I143,I143)=1,1,0) -> 0 | R143: =COUNTIF(O:O,O143) -> 5 | S143: =IF(COUNTIF(O$2:O143,O143)=1,R143,0)/2.5 -> 0
A144: SKU2 | B144: 1 | C144: 680 | D144: =C144+IF(INDEX('Справочник по %'!B:B,(MATCH(A144,'Справочник по %'!A:A,0)))="кол-во",B144*INDEX('Справочник по %'!C:C,(MATCH(A144,'Справочник по %'!A:A,0))),ОТЧЕТ!C144*INDEX('Справочник по %'!C:C,(MATCH(A144,'Справочник по %'!A:A,0))))/100 -> 680.2 | E144: =IF(ОТЧЕТ!A144="SKU3",C144+ОТЧЕТ!C144*0.2,C144+ОТЧЕТ!C144*0.15) -> 782 | F144: Ставропольский край, г Кисловодск, ул Куйбышева, д 66 | G144: 4702014562 | H144: Аптека | I144: =INDEX('Справочник Сети'!B:B,(MATCH(G144,'Справочник Сети'!C:C,0))) -> Ригла | J144: 2025-02-27 | K144: 19:15:00 | L144: 2025-02-27 | M144: 45715 | N144: 22:14:17 | O144: 2971 | P144: 1132 | Q144: =IF(COUNTIFS(A$2:A144,A144,I$2:I144,I144)=1,1,0) -> 1 | R144: =COUNTIF(O:O,O144) -> 3 | S144: =IF(COUNTIF(O$2:O144,O144)=1,R144,0)/2.5 -> 1.2
A145: SKU2 | B145: 1 | C145: 551 | D145: =C145+IF(INDEX('Справочник по %'!B:B,(MATCH(A145,'Справочник по %'!A:A,0)))="кол-во",B145*INDEX('Справочник по %'!C:C,(MATCH(A145,'Справочник по %'!A:A,0))),ОТЧЕТ!C145*INDEX('Справочник по %'!C:C,(MATCH(A145,'Справочник по %'!A:A,0))))/100 -> 551.2 | E145: =IF(ОТЧЕТ!A145="SKU3",C145+ОТЧЕТ!C145*0.2,C145+ОТЧЕТ!C145*0.15) -> 633.65 | F145: Ставропольский край, г Кисловодск, ул Куйбышева, д 66 | G145: 7706795062 | H145: Аптечный пункт-АФ-(Мск)-Планерная-1 | I145: =INDEX('Справочник Сети'!B:B,(MATCH(G145,'Справочник Сети'!C:C,0))) -> Планета здоровья | J145: 2025-02-03 | K145: 15:30:00 | L145: 2025-02-03 | M145: 45691 | N145: 22:53:21 | O145: 2109 | P145: 1137 | Q145: =IF(COUNTIFS(A$2:A145,A145,I$2:I145,I145)=1,1,0) -> 0 | R145: =COUNTIF(O:O,O145) -> 3 | S145: =IF(COUNTIF(O$2:O145,O145)=1,R145,0)/2.5 -> 1.2
A146: SKU2 | B146: 1 | C146: 554 | D146: =C146+IF(INDEX('Справочник по %'!B:B,(MATCH(A146,'Справочник по %'!A:A,0)))="кол-во",B146*INDEX('Справочник по %'!C:C,(MATCH(A146,'Справочник по %'!A:A,0))),ОТЧЕТ!C146*INDEX('Справочник по %'!C:C,(MATCH(A146,'Справочник по %'!A:A,0))))/100 -> 554.2 | E146: =IF(ОТЧЕТ!A146="SKU3",C146+ОТЧЕТ!C146*0.2,C146+ОТЧЕТ!C146*0.15) -> 637.1 | F146: Ставропольский край, г Кисловодск, ул Куйбышева, д 66 | G146: 7706795062 | H146: Аптечный пункт-АФ-(Мск)-Планерная-1 | I146: =INDEX('Справочник Сети'!B:B,(MATCH(G146,'Справочник Сети'!C:C,0))) -> Планета здоровья | J146: 2025-02-03 | K146: 15:30:00 | L146: 2025-02-03 | M146: 45691 | N146: 22:53:21 | O146: 2109 | P146: 1137 | Q146: =IF(COUNTIFS(A$2:A146,A146,I$2:I146,I146)=1,1,0) -> 0 | R146: =COUNTIF(O:O,O146) -> 3 | S146: =IF(COUNTIF(O$2:O146,O146)=1,R146,0)/2.5 -> 0
A147: SKU2 | B147: 1 | C147: 575 | D147: =C147+IF(INDEX('Справочник по %'!B:B,(MATCH(A147,'Справочник по %'!A:A,0)))="кол-во",B147*INDEX('Справочник по %'!C:C,(MATCH(A147,'Справочник по %'!A:A,0))),ОТЧЕТ!C147*INDEX('Справочник по %'!C:C,(MATCH(A147,'Справочник по %'!A:A,0))))/100 -> 575.2 | E147: =IF(ОТЧЕТ!A147="SKU3",C147+ОТЧЕТ!C147*0.2,C147+ОТЧЕТ!C147*0.15) -> 661.25 | F147: Ставропольский край, г Кисловодск, ул Куйбышева, д 66 | G147: 6950118467 | H147: Аптека | I147: =INDEX('Справочник Сети'!B:B,(MATCH(G147,'Справочник Сети'!C:C,0))) -> 0 | J147: 2025-02-06 | K147: 22:44:00 | L147: 2025-02-06 | M147: 45694 | N147: 23:41:00 | O147: 355 | P147: 1145 | Q147: =IF(COUNTIFS(A$2:A147,A147,I$2:I147,I147)=1,1,0) -> 1 | R147: =COUNTIF(O:O,O147) -> 2 | S147: =IF(COUNTIF(O$2:O147,O147)=1,R147,0)/2.5 -> 0.8
A148: SKU1 | B148: 1 | C148: 525 | D148: =C148+IF(INDEX('Справочник по %'!B:B,(MATCH(A148,'Справочник по %'!A:A,0)))="кол-во",B148*INDEX('Справочник по %'!C:C,(MATCH(A148,'Справочник по %'!A:A,0))),ОТЧЕТ!C148*INDEX('Справочник по %'!C:C,(MATCH(A148,'Справочник по %'!A:A,0))))/100 -> 577.5 | E148: =IF(ОТЧЕТ!A148="SKU3",C148+ОТЧЕТ!C148*0.2,C148+ОТЧЕТ!C148*0.15) -> 603.75 | F148: Ставропольский край, г Кисловодск, ул Куйбышева, д 66 | G148: 7840370306 | H148: АПТЕКА "Фармадом" | I148: =INDEX('Справочник Сети'!B:B,(MATCH(G148,'Справочник Сети'!C:C,0))) -> 0 | J148: 2025-01-13 | K148: 22:50:00 | L148: 2025-01-14 | M148: 45671 | N148: 23:47:44 | O148: 2296 | P148: 1147 | Q148: =IF(COUNTIFS(A$2:A148,A148,I$2:I148,I148)=1,1,0) -> 0 | R148: =COUNTIF(O:O,O148) -> 2 | S148: =IF(COUNTIF(O$2:O148,O148)=1,R148,0)/2.5 -> 0.8
A149: SKU2 | B149: 1 | C149: 749.5 | D149: =C149+IF(INDEX('Справочник по %'!B:B,(MATCH(A149,'Справочник по %'!A:A,0)))="кол-во",B149*INDEX('Справочник по %'!C:C,(MATCH(A149,'Справочник по %'!A:A,0))),ОТЧЕТ!C149*INDEX('Справочник по %'!C:C,(MATCH(A149,'Справочник по %'!A:A,0))))/100 -> 749.7 | E149: =IF(ОТЧЕТ!A149="SKU3",C149+ОТЧЕТ!C149*0.2,C149+ОТЧЕТ!C149*0.15) -> 861.925 | F149: Ставропольский край, г Кисловодск, ул Куйбышева, д 66 | G149: 7733179584 | H149: Аптека | I149: =INDEX('Справочник Сети'!B:B,(MATCH(G149,'Справочник Сети'!C:C,0))) -> Нео-фарм | J149: 2025-01-15 | K149: 00:02:00 | L149: 2025-01-16 | M149: 45673 | N149: 00:04:47 | O149: 1004 | P149: 1148 | Q149: =IF(COUNTIFS(A$2:A149,A149,I$2:I149,I149)=1,1,0) -> 0 | R149: =COUNTIF(O:O,O149) -> 1 | S149: =IF(COUNTIF(O$2:O149,O149)=1,R149,0)/2.5 -> 0.4
A150: SKU1 | B150: 1 | C150: 418.61 | D150: =C150+IF(INDEX('Справочник по %'!B:B,(MATCH(A150,'Справочник по %'!A:A,0)))="кол-во",B150*INDEX('Справочник по %'!C:C,(MATCH(A150,'Справочник по %'!A:A,0))),ОТЧЕТ!C150*INDEX('Справочник по %'!C:C,(MATCH(A150,'Справочник по %'!A:A,0))))/100 -> 460.471 | E150: =IF(ОТЧЕТ!A150="SKU3",C150+ОТЧЕТ!C150*0.2,C150+ОТЧЕТ!C150*0.15) -> 481.4015 | F150: Свердловская обл, г Невьянск, ул Ленина, д 4 | G150: 5507102175 | H150: Аптека | I150: =INDEX('Справочник Сети'!B:B,(MATCH(G150,'Справочник Сети'!C:C,0))) -> Столички | J150: 2025-02-25 | K150: 13:48:00 | L150: 2025-02-25 | M150: 45713 | N150: 11:05:14 | O150: 3288 | P150: 1579 | Q150: =IF(COUNTIFS(A$2:A150,A150,I$2:I150,I150)=1,1,0) -> 0 | R150: =COUNTIF(O:O,O150) -> 3 | S150: =IF(COUNTIF(O$2:O150,O150)=1,R150,0)/2.5 -> 1.2
...

Sheet Справочник Сети
A1: ИНН | B1: Аптечная сеть | C1: ИНН (числ.)
A2: 262810470121 | B2: 36,6 | C2: 262810470121
A3: 5402532406 | B3: 36,6 | C3: 5402532406
A4: 2310096546 | B4: 36,6 | C4: 2310096546
A5: 2373002156 | B5: 36,6 | C5: 2373002156
A6: 0600005787 | B6: 36,6 | C6: 600005787
A7: 5904196645 | B7: 36,6 | C7: 5904196645
A8: 7020028423 | B8: 36,6 | C8: 7020028423
A9: 2539096225 | B9: 36,6 | C9: 2539096225
A10: 550600087993 | B10: 36,6 | C10: 550600087993
A11: 2722039794 | B11: 36,6 | C11: 2722039794
A12: 4522002470 | B12: 36,6 | C12: 4522002470
A13: 7736325963 | B13: 36,6 | C13: 7736325963
... A406: 402701797950 | B406: Ригла | C406: 402701797950
A407: 3906313657 | C407: 3906313657
A408: 4253046074 | C408: 4253046074
A409: 7751007972 | C409: 7751007972
A410: 7802634533 | C410: 7802634533
A411: 6162043915 | C411: 6162043915
A412: 5408026558 | C412: 5408026558
A413: 2308120424 | C413: 2308120424
A414: 7728554303 | C414: 7728554303
A415: 9729056880 | C415: 9729056880
A416: 7715816671 | C416: 7715816671
A417: 3123226109 | C417: 3123226109
A418: 6166102417 | C418: 6166102417
... A467: 2227026014 | C467: 2227026014
A468: 7719840450 | C468: 7719840450
A469: 7720588903 | C469: 7720588903
A470: 1513045383 | C470: 1513045383
A471: 151504541439 | C471: 151504541439
A472: 7733556176 | C472: 7733556176
A473: 7719136780 | C473: 7719136780
A474: 6163055215 | C474: 6163055215
A475: 6950118467 | C475: 6950118467
A476: 1501019660 | C476: 1501019660
A477: 7840370306 | C477: 7840370306
A478: 2537044341 | C478: 2537044341
A479: 6321290768 | C479: 6321290768
A480: 5409012082 | C480: 5409012082
...

Sheet Справочник по %
B1: Тип комиссии | C1: размер комиссии | G1: Если тип комиссии "%", то сама комиссия расчитывается по формуле "стоимость товара" * "размер комиссии"
A2: SKU1 | B2: процент | C2: 10 | G2: Если тип комиссии "кол-во", то сама комиссия расчитывается по формуле "кол-во проданных уп" * "размер комиссии"
A3: SKU2 | B3: кол-во | C3: 20
A4: SKU3 | B4: процент | C4: 15
A5: SKU4 | B5: процент | C5: 10
